<sdf version='1.7'>
  <world name='default'>
    <light name='sun' type='directional'>
      <cast_shadows>1</cast_shadows>
      <pose>0 0 10 0 -0 0</pose>
      <diffuse>0.8 0.8 0.8 1</diffuse>
      <specular>0.2 0.2 0.2 1</specular>
      <attenuation>
        <range>1000</range>
        <constant>0.9</constant>
        <linear>0.01</linear>
        <quadratic>0.001</quadratic>
      </attenuation>
      <direction>-0.5 0.1 -0.9</direction>
      <spot>
        <inner_angle>0</inner_angle>
        <outer_angle>0</outer_angle>
        <falloff>0</falloff>
      </spot>
    </light>
    <model name='ground_plane'>
      <static>1</static>
      <link name='link'>
        <collision name='collision'>
          <geometry>
            <plane>
              <normal>0 0 1</normal>
              <size>100 100</size>
            </plane>
          </geometry>
          <surface>
            <friction>
              <ode>
                <mu>100</mu>
                <mu2>50</mu2>
              </ode>
              <torsional>
                <ode/>
              </torsional>
            </friction>
            <contact>
              <ode/>
            </contact>
            <bounce/>
          </surface>
          <max_contacts>10</max_contacts>
        </collision>
        <visual name='visual'>
          <cast_shadows>0</cast_shadows>
          <geometry>
            <plane>
              <normal>0 0 1</normal>
              <size>100 100</size>
            </plane>
          </geometry>
          <material>
            <script>
              <uri>file://media/materials/scripts/gazebo.material</uri>
              <name>Gazebo/Grey</name>
            </script>
          </material>
        </visual>
        <self_collide>0</self_collide>
        <enable_wind>0</enable_wind>
        <kinematic>0</kinematic>
      </link>
    </model>
    <gravity>0 0 -9.8</gravity>
    <magnetic_field>6e-06 2.3e-05 -4.2e-05</magnetic_field>
    <atmosphere type='adiabatic'/>
    <physics type='ode'>
      <max_step_size>0.001</max_step_size>
      <real_time_factor>1</real_time_factor>
      <real_time_update_rate>1000</real_time_update_rate>
    </physics>
    <scene>
      <ambient>0.4 0.4 0.4 1</ambient>
      <background>0.7 0.7 0.7 1</background>
      <shadows>1</shadows>
    </scene>
    <wind/>
    <spherical_coordinates>
      <surface_model>EARTH_WGS84</surface_model>
      <latitude_deg>0</latitude_deg>
      <longitude_deg>0</longitude_deg>
      <elevation>0</elevation>
      <heading_deg>0</heading_deg>
    </spherical_coordinates>
    <model name='SIM_CER_ROBOT'>
      <link name='mobile_base_body_link'>
        <pose>0 0 0 0 -0 0</pose>
        <inertial>
          <pose>0.003532 0 0.062803 0 -0 0</pose>
          <mass>14</mass>
          <inertia>
            <ixx>0.342401</ixx>
            <ixy>0</ixy>
            <ixz>-0.0396992</ixz>
            <iyy>0.362542</iyy>
            <iyz>0</iyz>
            <izz>0.168981</izz>
          </inertia>
        </inertial>
        <collision name='mobile_base_body_link_collision'>
          <pose>0 0 -0.16 0 -0 0</pose>
          <geometry>
            <mesh>
              <scale>0.001 0.001 0.001</scale>
              <uri>model://cer/meshes/obj/sim_cer_mobilebase_body.obj</uri>
            </mesh>
          </geometry>
          <surface>
            <contact>
              <ode/>
            </contact>
            <friction>
              <ode>
                <mu>0</mu>
                <mu2>0</mu2>
              </ode>
              <torsional>
                <ode/>
              </torsional>
            </friction>
            <bounce/>
          </surface>
          <max_contacts>10</max_contacts>
        </collision>
        <visual name='mobile_base_body_link_visual'>
          <pose>0 0 -0.16 0 -0 0</pose>
          <geometry>
            <mesh>
              <scale>0.001 0.001 0.001</scale>
              <uri>model://cer/meshes/obj/sim_cer_mobilebase_body.obj</uri>
            </mesh>
          </geometry>
          <material>
            <script>
              <uri>__default__</uri>
              <name>__default__</name>
            </script>
          </material>
        </visual>
        <velocity_decay/>
        <sensor name='base_laser' type='ray'>
          <always_on>1</always_on>
          <update_rate>40</update_rate>
          <pose>0.07 0 0.031 0 -0 0</pose>
          <visualize>1</visualize>
          <ray>
            <scan>
              <horizontal>
                <samples>360</samples>
                <resolution>2</resolution>
                <min_angle>0</min_angle>
                <max_angle>6.28</max_angle>
              </horizontal>
              <vertical>
                <samples>1</samples>
                <min_angle>0</min_angle>
                <max_angle>0</max_angle>
              </vertical>
            </scan>
            <range>
              <min>0.04</min>
              <max>5</max>
              <resolution>0.01</resolution>
            </range>
            <noise>
              <type>gaussian</type>
              <mean>0</mean>
              <stddev>0.005</stddev>
            </noise>
          </ray>
          <plugin name='laser_sensor' filename='libgazebo_yarp_lasersensor.so'>
            <yarpConfigurationFile>model://cer/conf/gazebo_cer_laser_sensor.ini</yarpConfigurationFile>
          </plugin>
        </sensor>
        <sensor name='base_laser2' type='ray'>
          <always_on>1</always_on>
          <update_rate>40</update_rate>
          <pose>-0.085 0 0.031 0 -0 3.14159</pose>
          <visualize>1</visualize>
          <ray>
            <scan>
              <horizontal>
                <samples>360</samples>
                <resolution>2</resolution>
                <min_angle>0</min_angle>
                <max_angle>6.28</max_angle>
              </horizontal>
              <vertical>
                <samples>1</samples>
                <min_angle>0</min_angle>
                <max_angle>0</max_angle>
              </vertical>
            </scan>
            <range>
              <min>0.04</min>
              <max>5</max>
              <resolution>0.01</resolution>
            </range>
            <noise>
              <type>gaussian</type>
              <mean>0</mean>
              <stddev>0.005</stddev>
            </noise>
          </ray>
          <plugin name='laser_sensor2' filename='libgazebo_yarp_lasersensor.so'>
            <yarpConfigurationFile>model://cer/conf/gazebo_cer_laser_sensor2.ini</yarpConfigurationFile>
          </plugin>
        </sensor>
        <gravity>1</gravity>
        <velocity_decay/>
        <self_collide>0</self_collide>
        <enable_wind>0</enable_wind>
        <kinematic>0</kinematic>
      </link>
      <link name='mobile_base_l_tyre_link'>
        <pose>0 0.139 0 0 -0 0</pose>
        <inertial>
          <pose>0 0.034425 9e-06 0 -0 0</pose>
          <mass>3</mass>
          <inertia>
            <ixx>0.0200196</ixx>
            <ixy>0</ixy>
            <ixz>0</ixz>
            <iyy>0.0376169</iyy>
            <iyz>-8.28446e-07</iyz>
            <izz>0.0200156</izz>
          </inertia>
        </inertial>
        <collision name='mobile_base_l_tyre_link_collision'>
          <pose>0 0.03 0 1.5708 -0 0</pose>
          <geometry>
            <cylinder>
              <length>0.005</length>
              <radius>0.16</radius>
            </cylinder>
          </geometry>
          <max_contacts>10</max_contacts>
          <surface>
            <contact>
              <ode/>
            </contact>
            <bounce/>
            <friction>
              <torsional>
                <ode/>
              </torsional>
              <ode/>
            </friction>
          </surface>
        </collision>
        <visual name='mobile_base_l_tyre_link_visual'>
          <pose>0 -0.139 -0.16 0 -0 0</pose>
          <geometry>
            <mesh>
              <scale>0.001 0.001 0.001</scale>
              <uri>model://cer/meshes/dae/sim_cer_mobilebase_l_tyre.dae</uri>
            </mesh>
          </geometry>
        </visual>
        <self_collide>0</self_collide>
        <enable_wind>0</enable_wind>
        <kinematic>0</kinematic>
      </link>
      <joint name='mobile_base_l_wheel_joint' type='revolute'>
        <child>mobile_base_l_tyre_link</child>
        <parent>mobile_base_body_link</parent>
        <axis>
          <xyz expressed_in='__model__'>0 1 0</xyz>
          <limit>
            <lower>-1e+16</lower>
            <upper>1e+16</upper>
          </limit>
          <dynamics>
            <damping>0.5</damping>
            <friction>0</friction>
            <spring_reference>0</spring_reference>
            <spring_stiffness>0</spring_stiffness>
          </dynamics>
        </axis>
        <physics>
          <ode>
            <implicit_spring_damper>1</implicit_spring_damper>
            <cfm_damping>1</cfm_damping>
            <limit>
              <cfm>0</cfm>
              <erp>0.2</erp>
            </limit>
          </ode>
        </physics>
      </joint>
      <link name='mobile_base_r_tyre_link'>
        <pose>0 -0.139 0 0 -0 0</pose>
        <inertial>
          <pose>0 -0.034425 9e-06 0 -0 0</pose>
          <mass>3</mass>
          <inertia>
            <ixx>0.0200196</ixx>
            <ixy>0</ixy>
            <ixz>0</ixz>
            <iyy>0.0376169</iyy>
            <iyz>8.28101e-07</iyz>
            <izz>0.0200156</izz>
          </inertia>
        </inertial>
        <collision name='mobile_base_r_tyre_link_collision'>
          <pose>0 -0.03 0 1.5708 -0 0</pose>
          <geometry>
            <cylinder>
              <length>0.005</length>
              <radius>0.16</radius>
            </cylinder>
          </geometry>
          <max_contacts>10</max_contacts>
          <surface>
            <contact>
              <ode/>
            </contact>
            <bounce/>
            <friction>
              <torsional>
                <ode/>
              </torsional>
              <ode/>
            </friction>
          </surface>
        </collision>
        <visual name='mobile_base_r_tyre_link_visual'>
          <pose>0 0.139 -0.16 0 -0 0</pose>
          <geometry>
            <mesh>
              <scale>0.001 0.001 0.001</scale>
              <uri>model://cer/meshes/dae/sim_cer_mobilebase_r_tyre.dae</uri>
            </mesh>
          </geometry>
        </visual>
        <self_collide>0</self_collide>
        <enable_wind>0</enable_wind>
        <kinematic>0</kinematic>
      </link>
      <joint name='mobile_base_r_wheel_joint' type='revolute'>
        <child>mobile_base_r_tyre_link</child>
        <parent>mobile_base_body_link</parent>
        <axis>
          <xyz expressed_in='__model__'>0 1 0</xyz>
          <limit>
            <lower>-1e+16</lower>
            <upper>1e+16</upper>
          </limit>
          <dynamics>
            <damping>0.5</damping>
            <friction>0</friction>
            <spring_reference>0</spring_reference>
            <spring_stiffness>0</spring_stiffness>
          </dynamics>
        </axis>
        <physics>
          <ode>
            <implicit_spring_damper>1</implicit_spring_damper>
            <cfm_damping>1</cfm_damping>
            <limit>
              <cfm>0</cfm>
              <erp>0.2</erp>
            </limit>
          </ode>
        </physics>
      </joint>
      <link name='torso_slider_eq_link'>
        <pose>0.044 0 0.071 0 -0 0</pose>
        <inertial>
          <pose>0.015175 3e-06 0.244533 0 -0 0</pose>
          <mass>7.5</mass>
          <inertia>
            <ixx>0.0978792</ixx>
            <ixy>-1.83466e-06</ixy>
            <ixz>0.00625726</ixz>
            <iyy>0.0969511</iyy>
            <iyz>0</iyz>
            <izz>0.0746114</izz>
          </inertia>
        </inertial>
        <collision name='torso_slider_eq_link_collision'>
          <pose>-0.044 0 -0.231 0 -0 0</pose>
          <geometry>
            <mesh>
              <scale>0.001 0.001 0.001</scale>
              <uri>model://cer/meshes/dae/sim_cer_torso_slider_eq.dae</uri>
            </mesh>
          </geometry>
          <max_contacts>10</max_contacts>
          <surface>
            <contact>
              <ode/>
            </contact>
            <bounce/>
            <friction>
              <torsional>
                <ode/>
              </torsional>
              <ode/>
            </friction>
          </surface>
        </collision>
        <visual name='torso_slider_eq_link_visual'>
          <pose>-0.044 0 -0.231 0 -0 0</pose>
          <geometry>
            <mesh>
              <scale>0.001 0.001 0.001</scale>
              <uri>model://cer/meshes/dae/sim_cer_torso_slider_eq.dae</uri>
            </mesh>
          </geometry>
        </visual>
        <self_collide>0</self_collide>
        <enable_wind>0</enable_wind>
        <kinematic>0</kinematic>
      </link>
      <joint name='torso_heave_eq_joint' type='prismatic'>
        <child>torso_slider_eq_link</child>
        <parent>mobile_base_body_link</parent>
        <axis>
          <xyz expressed_in='__model__'>0 0 1</xyz>
          <limit>
            <lower>0</lower>
            <upper>0.17</upper>
            <effort>1200</effort>
            <velocity>0.5</velocity>
          </limit>
          <dynamics>
            <damping>1000</damping>
            <friction>0</friction>
            <spring_reference>0</spring_reference>
            <spring_stiffness>0</spring_stiffness>
          </dynamics>
        </axis>
        <physics>
          <ode>
            <implicit_spring_damper>1</implicit_spring_damper>
            <cfm_damping>1</cfm_damping>
            <limit>
              <cfm>0</cfm>
              <erp>0.2</erp>
            </limit>
          </ode>
        </physics>
      </joint>
      <link name='torso_pin_eq_link'>
        <pose>0.044 0 0.47 -3.14159 -0 0</pose>
        <inertial>
          <pose>0 0 0 0 -0 0</pose>
          <mass>1.5</mass>
          <inertia>
            <ixx>0.000379688</ixx>
            <ixy>0</ixy>
            <ixz>0</ixz>
            <iyy>0.00143984</iyy>
            <iyz>0</iyz>
            <izz>0.00143984</izz>
          </inertia>
        </inertial>
        <collision name='torso_pin_eq_link_collision'>
          <pose>0 0 0 0 -0 0</pose>
          <geometry>
            <mesh>
              <scale>0.001 0.001 0.001</scale>
              <uri>model://cer/meshes/dae/sim_cer_torso_pin_eq.dae</uri>
            </mesh>
          </geometry>
          <max_contacts>10</max_contacts>
          <surface>
            <contact>
              <ode/>
            </contact>
            <bounce/>
            <friction>
              <torsional>
                <ode/>
              </torsional>
              <ode/>
            </friction>
          </surface>
        </collision>
        <visual name='torso_pin_eq_link_visual'>
          <pose>0 0 0 0 -0 0</pose>
          <geometry>
            <mesh>
              <scale>0.001 0.001 0.001</scale>
              <uri>model://cer/meshes/dae/sim_cer_torso_pin_eq.dae</uri>
            </mesh>
          </geometry>
        </visual>
        <self_collide>0</self_collide>
        <enable_wind>0</enable_wind>
        <kinematic>0</kinematic>
      </link>
      <joint name='torso_roll_eq_joint' type='revolute'>
        <child>torso_pin_eq_link</child>
        <parent>torso_slider_eq_link</parent>
        <axis>
          <xyz expressed_in='__model__'>1 0 0</xyz>
          <limit>
            <lower>-0.523599</lower>
            <upper>0.523599</upper>
            <effort>50</effort>
            <velocity>3.14</velocity>
          </limit>
          <dynamics>
            <damping>100</damping>
            <friction>0</friction>
            <spring_reference>0</spring_reference>
            <spring_stiffness>0</spring_stiffness>
          </dynamics>
        </axis>
        <physics>
          <ode>
            <implicit_spring_damper>1</implicit_spring_damper>
            <cfm_damping>1</cfm_damping>
            <limit>
              <cfm>0</cfm>
              <erp>0.2</erp>
            </limit>
          </ode>
        </physics>
      </joint>
      <link name='torso_platform_link'>
        <pose>0.044 0 0.47 0 -0 0</pose>
        <inertial>
          <pose>0 0 0 0 -0 0</pose>
          <mass>1.5</mass>
          <inertia>
            <ixx>0.00153125</ixx>
            <ixy>0</ixy>
            <ixz>0</ixz>
            <iyy>0.00153125</iyy>
            <iyz>0</iyz>
            <izz>0.0030375</izz>
          </inertia>
        </inertial>
        <collision name='torso_platform_link_collision'>
          <pose>-0.044 0 -0.63 0 -0 0</pose>
          <geometry>
            <mesh>
              <scale>0.001 0.001 0.001</scale>
              <uri>model://cer/meshes/dae/sim_cer_torso_platform.dae</uri>
            </mesh>
          </geometry>
          <max_contacts>10</max_contacts>
          <surface>
            <contact>
              <ode/>
            </contact>
            <bounce/>
            <friction>
              <torsional>
                <ode/>
              </torsional>
              <ode/>
            </friction>
          </surface>
        </collision>
        <visual name='torso_platform_link_visual'>
          <pose>-0.044 0 -0.63 0 -0 0</pose>
          <geometry>
            <mesh>
              <scale>0.001 0.001 0.001</scale>
              <uri>model://cer/meshes/dae/sim_cer_torso_platform.dae</uri>
            </mesh>
          </geometry>
        </visual>
        <self_collide>0</self_collide>
        <enable_wind>0</enable_wind>
        <kinematic>0</kinematic>
      </link>
      <joint name='torso_pitch_eq_joint' type='revolute'>
        <child>torso_platform_link</child>
        <parent>torso_pin_eq_link</parent>
        <axis>
          <xyz expressed_in='__model__'>0 1 0</xyz>
          <limit>
            <lower>-0.523599</lower>
            <upper>0.523599</upper>
            <effort>50</effort>
            <velocity>3.14</velocity>
          </limit>
          <dynamics>
            <damping>100</damping>
            <friction>0</friction>
            <spring_reference>0</spring_reference>
            <spring_stiffness>0</spring_stiffness>
          </dynamics>
        </axis>
        <physics>
          <ode>
            <implicit_spring_damper>1</implicit_spring_damper>
            <cfm_damping>1</cfm_damping>
            <limit>
              <cfm>0</cfm>
              <erp>0.2</erp>
            </limit>
          </ode>
        </physics>
      </joint>
      <link name='chest_link'>
        <pose>0.044 0 0.47 0 -0 0</pose>
        <inertial>
          <pose>-0.033031 0 0.220198 0 -0 0</pose>
          <mass>13</mass>
          <inertia>
            <ixx>0.275816</ixx>
            <ixy>0</ixy>
            <ixz>0.0564476</ixz>
            <iyy>0.253579</iyy>
            <iyz>0</iyz>
            <izz>0.127156</izz>
          </inertia>
        </inertial>
        <collision name='chest_link_collision'>
          <pose>-0.044 0 -0.63 0 -0 0</pose>
          <geometry>
            <mesh>
              <scale>0.001 0.001 0.001</scale>
              <uri>model://cer/meshes/dae/sim_cer_chest.dae</uri>
            </mesh>
          </geometry>
          <max_contacts>10</max_contacts>
          <surface>
            <contact>
              <ode/>
            </contact>
            <bounce/>
            <friction>
              <torsional>
                <ode/>
              </torsional>
              <ode/>
            </friction>
          </surface>
        </collision>
        <visual name='chest_link_visual'>
          <pose>-0.044 0 -0.63 0 -0 0</pose>
          <geometry>
            <mesh>
              <scale>0.001 0.001 0.001</scale>
              <uri>model://cer/meshes/dae/sim_cer_chest.dae</uri>
            </mesh>
          </geometry>
        </visual>
        <self_collide>0</self_collide>
        <enable_wind>0</enable_wind>
        <kinematic>0</kinematic>
      </link>
      <joint name='torso_yaw_joint' type='revolute'>
        <child>chest_link</child>
        <parent>torso_platform_link</parent>
        <axis>
          <xyz expressed_in='__model__'>-0 -0 1</xyz>
          <limit>
            <lower>-1.0472</lower>
            <upper>1.0472</upper>
            <effort>30</effort>
            <velocity>3.14</velocity>
          </limit>
          <dynamics>
            <damping>10</damping>
            <friction>0</friction>
            <spring_reference>0</spring_reference>
            <spring_stiffness>0</spring_stiffness>
          </dynamics>
        </axis>
        <physics>
          <ode>
            <implicit_spring_damper>1</implicit_spring_damper>
            <cfm_damping>1</cfm_damping>
            <limit>
              <cfm>0</cfm>
              <erp>0.2</erp>
            </limit>
          </ode>
        </physics>
      </joint>
      <link name='l_clavicle_link'>
        <pose>-0.04 0.177 0.84 0 -0 0</pose>
        <inertial>
          <pose>0 0 0 0 -0 0</pose>
          <mass>0.2</mass>
          <inertia>
            <ixx>0.000288</ixx>
            <ixy>0</ixy>
            <ixz>0</ixz>
            <iyy>0.000288</iyy>
            <iyz>0</iyz>
            <izz>0.000288</izz>
          </inertia>
        </inertial>
        <collision name='l_clavicle_link_collision'>
          <pose>0.04 -0.177 -1 0 -0 0</pose>
          <geometry>
            <mesh>
              <scale>0.001 0.001 0.001</scale>
              <uri>model://cer/meshes/dae/sim_cer_l_clavicle.dae</uri>
            </mesh>
          </geometry>
          <max_contacts>10</max_contacts>
          <surface>
            <contact>
              <ode/>
            </contact>
            <bounce/>
            <friction>
              <torsional>
                <ode/>
              </torsional>
              <ode/>
            </friction>
          </surface>
        </collision>
        <visual name='l_clavicle_link_visual'>
          <pose>0.04 -0.177 -1 0 -0 0</pose>
          <geometry>
            <mesh>
              <scale>0.001 0.001 0.001</scale>
              <uri>model://cer/meshes/dae/sim_cer_l_clavicle.dae</uri>
            </mesh>
          </geometry>
        </visual>
        <self_collide>0</self_collide>
        <enable_wind>0</enable_wind>
        <kinematic>0</kinematic>
      </link>
      <joint name='l_shoulder_pitch_joint' type='revolute'>
        <child>l_clavicle_link</child>
        <parent>chest_link</parent>
        <axis>
          <xyz expressed_in='__model__'>0 -0.970296 -0.241922</xyz>
          <limit>
            <lower>-0.523599</lower>
            <upper>1.5708</upper>
            <effort>30</effort>
            <velocity>3.14</velocity>
          </limit>
          <dynamics>
            <damping>10</damping>
            <friction>0</friction>
            <spring_reference>0</spring_reference>
            <spring_stiffness>0</spring_stiffness>
          </dynamics>
        </axis>
        <physics>
          <ode>
            <implicit_spring_damper>1</implicit_spring_damper>
            <cfm_damping>1</cfm_damping>
            <limit>
              <cfm>0</cfm>
              <erp>0.2</erp>
            </limit>
          </ode>
        </physics>
      </joint>
      <link name='l_shoulder_link'>
        <pose>-0.04 0.177 0.84 0 -0 0</pose>
        <inertial>
          <pose>2e-06 0.042148 -0.06332 0 -0 0</pose>
          <mass>0.5</mass>
          <inertia>
            <ixx>0.00076143</ixx>
            <ixy>0</ixy>
            <ixz>-2.84061e-08</ixz>
            <iyy>0.000819748</iyy>
            <iyz>-0.000135828</iyz>
            <izz>0.000588486</izz>
          </inertia>
        </inertial>
        <collision name='l_shoulder_link_collision'>
          <pose>0.04 -0.177 -1 0 -0 0</pose>
          <geometry>
            <mesh>
              <scale>0.001 0.001 0.001</scale>
              <uri>model://cer/meshes/dae/sim_cer_l_shoulder.dae</uri>
            </mesh>
          </geometry>
          <max_contacts>10</max_contacts>
          <surface>
            <contact>
              <ode/>
            </contact>
            <bounce/>
            <friction>
              <torsional>
                <ode/>
              </torsional>
              <ode/>
            </friction>
          </surface>
        </collision>
        <visual name='l_shoulder_link_visual'>
          <pose>0.04 -0.177 -1 0 -0 0</pose>
          <geometry>
            <mesh>
              <scale>0.001 0.001 0.001</scale>
              <uri>model://cer/meshes/dae/sim_cer_l_shoulder.dae</uri>
            </mesh>
          </geometry>
        </visual>
        <self_collide>0</self_collide>
        <enable_wind>0</enable_wind>
        <kinematic>0</kinematic>
      </link>
      <joint name='l_shoulder_roll_joint' type='revolute'>
        <child>l_shoulder_link</child>
        <parent>l_clavicle_link</parent>
        <axis>
          <xyz expressed_in='__model__'>1 -0 0</xyz>
          <limit>
            <lower>-0.174533</lower>
            <upper>1.309</upper>
            <effort>30</effort>
            <velocity>3.14</velocity>
          </limit>
          <dynamics>
            <damping>10</damping>
            <friction>0</friction>
            <spring_reference>0</spring_reference>
            <spring_stiffness>0</spring_stiffness>
          </dynamics>
        </axis>
        <physics>
          <ode>
            <implicit_spring_damper>1</implicit_spring_damper>
            <cfm_damping>1</cfm_damping>
            <limit>
              <cfm>0</cfm>
              <erp>0.2</erp>
            </limit>
          </ode>
        </physics>
      </joint>
      <link name='l_upperarm_FT_sensor_link'>
        <pose>-0.04 0.211 0.73 0 -0 0</pose>
        <inertial>
          <pose>-0.000784 -0.000123 -0.042763 0 -0 0</pose>
          <mass>0.8</mass>
          <inertia>
            <ixx>0.0012924</ixx>
            <ixy>-4.63196e-08</ixy>
            <ixz>-4.45408e-05</ixz>
            <iyy>0.00128408</iyy>
            <iyz>-1.2213e-06</iyz>
            <izz>0.000657768</izz>
          </inertia>
        </inertial>
        <collision name='l_upperarm_FT_sensor_link_collision'>
          <pose>0.04 -0.211 -0.89 0 -0 0</pose>
          <geometry>
            <mesh>
              <scale>0.001 0.001 0.001</scale>
              <uri>model://cer/meshes/dae/sim_cer_l_upperarm_sensor.dae</uri>
            </mesh>
          </geometry>
          <max_contacts>10</max_contacts>
          <surface>
            <contact>
              <ode/>
            </contact>
            <bounce/>
            <friction>
              <torsional>
                <ode/>
              </torsional>
              <ode/>
            </friction>
          </surface>
        </collision>
        <collision name='l_upperarm_FT_sensor_link_fixed_joint_lump__l_upperarm_link_collision_1'>
          <pose>0.04 -0.211 -0.89 0 -0 0</pose>
          <geometry>
            <mesh>
              <scale>0.001 0.001 0.001</scale>
              <uri>model://cer/meshes/dae/sim_cer_l_upperarm.dae</uri>
            </mesh>
          </geometry>
          <max_contacts>10</max_contacts>
          <surface>
            <contact>
              <ode/>
            </contact>
            <bounce/>
            <friction>
              <torsional>
                <ode/>
              </torsional>
              <ode/>
            </friction>
          </surface>
        </collision>
        <visual name='l_upperarm_FT_sensor_link_visual'>
          <pose>0.04 -0.211 -0.89 0 -0 0</pose>
          <geometry>
            <mesh>
              <scale>0.001 0.001 0.001</scale>
              <uri>model://cer/meshes/dae/sim_cer_l_upperarm_sensor.dae</uri>
            </mesh>
          </geometry>
        </visual>
        <visual name='l_upperarm_FT_sensor_link_fixed_joint_lump__l_upperarm_link_visual_1'>
          <pose>0.04 -0.211 -0.89 0 -0 0</pose>
          <geometry>
            <mesh>
              <scale>0.001 0.001 0.001</scale>
              <uri>model://cer/meshes/dae/sim_cer_l_upperarm.dae</uri>
            </mesh>
          </geometry>
        </visual>
        <self_collide>0</self_collide>
        <enable_wind>0</enable_wind>
        <kinematic>0</kinematic>
      </link>
      <joint name='l_shoulder_yaw_joint' type='revolute'>
        <child>l_upperarm_FT_sensor_link</child>
        <parent>l_shoulder_link</parent>
        <axis>
          <xyz expressed_in='__model__'>-0 -0 1</xyz>
          <limit>
            <lower>-1.5708</lower>
            <upper>1.5708</upper>
            <effort>15</effort>
            <velocity>3.14</velocity>
          </limit>
          <dynamics>
            <damping>10</damping>
            <friction>0</friction>
            <spring_reference>0</spring_reference>
            <spring_stiffness>0</spring_stiffness>
          </dynamics>
        </axis>
        <physics>
          <ode>
            <implicit_spring_damper>1</implicit_spring_damper>
            <cfm_damping>1</cfm_damping>
            <limit>
              <cfm>0</cfm>
              <erp>0.2</erp>
            </limit>
          </ode>
        </physics>
      </joint>
      <link name='l_elbow_sphere_link'>
        <pose>-0.04 0.211 0.589 0 -0 0</pose>
        <inertial>
          <pose>0 0 0 0 -0 0</pose>
          <mass>0.2</mass>
          <inertia>
            <ixx>0.000128</ixx>
            <ixy>0</ixy>
            <ixz>0</ixz>
            <iyy>0.000128</iyy>
            <iyz>0</iyz>
            <izz>0.000128</izz>
          </inertia>
        </inertial>
        <collision name='l_elbow_sphere_link_collision'>
          <pose>0.04 -0.211 -0.749 0 -0 0</pose>
          <geometry>
            <mesh>
              <scale>0.001 0.001 0.001</scale>
              <uri>model://cer/meshes/dae/sim_cer_l_elbow_sphere.dae</uri>
            </mesh>
          </geometry>
          <max_contacts>10</max_contacts>
          <surface>
            <contact>
              <ode/>
            </contact>
            <bounce/>
            <friction>
              <torsional>
                <ode/>
              </torsional>
              <ode/>
            </friction>
          </surface>
        </collision>
        <visual name='l_elbow_sphere_link_visual'>
          <pose>0.04 -0.211 -0.749 0 -0 0</pose>
          <geometry>
            <mesh>
              <scale>0.001 0.001 0.001</scale>
              <uri>model://cer/meshes/dae/sim_cer_l_elbow_sphere.dae</uri>
            </mesh>
          </geometry>
        </visual>
        <self_collide>0</self_collide>
        <enable_wind>0</enable_wind>
        <kinematic>0</kinematic>
      </link>
      <joint name='l_elbow_joint' type='revolute'>
        <child>l_elbow_sphere_link</child>
        <parent>l_upperarm_FT_sensor_link</parent>
        <axis>
          <xyz expressed_in='__model__'>-0 -1 -0</xyz>
          <limit>
            <lower>0</lower>
            <upper>1.74533</upper>
            <effort>20</effort>
            <velocity>3.14</velocity>
          </limit>
          <dynamics>
            <damping>10</damping>
            <friction>0</friction>
            <spring_reference>0</spring_reference>
            <spring_stiffness>0</spring_stiffness>
          </dynamics>
        </axis>
        <physics>
          <ode>
            <implicit_spring_damper>1</implicit_spring_damper>
            <cfm_damping>1</cfm_damping>
            <limit>
              <cfm>0</cfm>
              <erp>0.2</erp>
            </limit>
          </ode>
        </physics>
      </joint>
      <link name='l_forearm_link'>
        <pose>-0.04 0.211 0.518 0 -0 0</pose>
        <inertial>
          <pose>-0.000512 -0.000175 -0.072511 0 -0 0</pose>
          <mass>0.6</mass>
          <inertia>
            <ixx>0.00283352</ixx>
            <ixy>0</ixy>
            <ixz>3.15449e-05</ixz>
            <iyy>0.00282953</iyy>
            <iyz>1.0379e-07</iyz>
            <izz>0.000436673</izz>
          </inertia>
        </inertial>
        <collision name='l_forearm_link_collision'>
          <pose>0.04 -0.211 -0.678 0 -0 0</pose>
          <geometry>
            <mesh>
              <scale>0.001 0.001 0.001</scale>
              <uri>model://cer/meshes/dae/sim_cer_l_forearm.dae</uri>
            </mesh>
          </geometry>
          <max_contacts>10</max_contacts>
          <surface>
            <contact>
              <ode/>
            </contact>
            <bounce/>
            <friction>
              <torsional>
                <ode/>
              </torsional>
              <ode/>
            </friction>
          </surface>
        </collision>
        <visual name='l_forearm_link_visual'>
          <pose>0.04 -0.211 -0.678 0 -0 0</pose>
          <geometry>
            <mesh>
              <scale>0.001 0.001 0.001</scale>
              <uri>model://cer/meshes/dae/sim_cer_l_forearm.dae</uri>
            </mesh>
          </geometry>
        </visual>
        <self_collide>0</self_collide>
        <enable_wind>0</enable_wind>
        <kinematic>0</kinematic>
      </link>
      <joint name='l_wrist_pronosupination_joint' type='revolute'>
        <child>l_forearm_link</child>
        <parent>l_elbow_sphere_link</parent>
        <axis>
          <xyz expressed_in='__model__'>0 -0 1</xyz>
          <limit>
            <lower>-1.5708</lower>
            <upper>1.5708</upper>
            <effort>10</effort>
            <velocity>3.14</velocity>
          </limit>
          <dynamics>
            <damping>10</damping>
            <friction>0</friction>
            <spring_reference>0</spring_reference>
            <spring_stiffness>0</spring_stiffness>
          </dynamics>
        </axis>
        <physics>
          <ode>
            <implicit_spring_damper>1</implicit_spring_damper>
            <cfm_damping>1</cfm_damping>
            <limit>
              <cfm>0</cfm>
              <erp>0.2</erp>
            </limit>
          </ode>
        </physics>
      </joint>
      <link name='l_wrist_slider_eq_link'>
        <pose>-0.04 0.211 0.589 0 -0 0</pose>
        <inertial>
          <pose>0 -5.9e-05 -0.225761 0 -0 0</pose>
          <mass>0.3</mass>
          <inertia>
            <ixx>0.000939997</ixx>
            <ixy>0</ixy>
            <ixz>0</ixz>
            <iyy>0.00094</iyy>
            <iyz>4.18243e-09</iyz>
            <izz>0.000220942</izz>
          </inertia>
        </inertial>
        <collision name='l_wrist_slider_eq_link_collision'>
          <pose>0.04 -0.211 -0.749 0 -0 0</pose>
          <geometry>
            <mesh>
              <scale>0.001 0.001 0.001</scale>
              <uri>model://cer/meshes/dae/sim_cer_l_wrist_slider.dae</uri>
            </mesh>
          </geometry>
          <max_contacts>10</max_contacts>
          <surface>
            <contact>
              <ode/>
            </contact>
            <bounce/>
            <friction>
              <torsional>
                <ode/>
              </torsional>
              <ode/>
            </friction>
          </surface>
        </collision>
        <visual name='l_wrist_slider_eq_link_visual'>
          <pose>0.04 -0.211 -0.749 0 -0 0</pose>
          <geometry>
            <mesh>
              <scale>0.001 0.001 0.001</scale>
              <uri>model://cer/meshes/dae/sim_cer_l_wrist_slider.dae</uri>
            </mesh>
          </geometry>
        </visual>
        <self_collide>0</self_collide>
        <enable_wind>0</enable_wind>
        <kinematic>0</kinematic>
      </link>
      <joint name='l_wrist_heave_eq_joint' type='prismatic'>
        <child>l_wrist_slider_eq_link</child>
        <parent>l_forearm_link</parent>
        <axis>
          <xyz expressed_in='__model__'>-0 0 -1</xyz>
          <limit>
            <lower>0</lower>
            <upper>0.13</upper>
            <effort>200</effort>
            <velocity>0.25</velocity>
          </limit>
          <dynamics>
            <damping>100</damping>
            <friction>0</friction>
            <spring_reference>0</spring_reference>
            <spring_stiffness>0</spring_stiffness>
          </dynamics>
        </axis>
        <physics>
          <ode>
            <implicit_spring_damper>1</implicit_spring_damper>
            <cfm_damping>1</cfm_damping>
            <limit>
              <cfm>0</cfm>
              <erp>0.2</erp>
            </limit>
          </ode>
        </physics>
      </joint>
      <link name='l_wrist_cup_eq_link'>
        <pose>-0.072 0.211 0.298 0 -0 0</pose>
        <inertial>
          <pose>0.031989 -5.9e-05 -0.018146 0 -0 0</pose>
          <mass>0.2</mass>
          <inertia>
            <ixx>0.000102239</ixx>
            <ixy>0</ixy>
            <ixz>3.78925e-08</ixz>
            <iyy>0.000102239</iyy>
            <iyz>0</iyz>
            <izz>0.000163555</izz>
          </inertia>
        </inertial>
        <collision name='l_wrist_cup_eq_link_collision'>
          <pose>0.072 -0.211 -0.458 0 -0 0</pose>
          <geometry>
            <mesh>
              <scale>0.001 0.001 0.001</scale>
              <uri>model://cer/meshes/dae/sim_cer_l_wrist_cup_eq.dae</uri>
            </mesh>
          </geometry>
          <max_contacts>10</max_contacts>
          <surface>
            <contact>
              <ode/>
            </contact>
            <bounce/>
            <friction>
              <torsional>
                <ode/>
              </torsional>
              <ode/>
            </friction>
          </surface>
        </collision>
        <visual name='l_wrist_cup_eq_link_visual'>
          <pose>0.072 -0.211 -0.458 0 -0 0</pose>
          <geometry>
            <mesh>
              <scale>0.001 0.001 0.001</scale>
              <uri>model://cer/meshes/dae/sim_cer_l_wrist_cup_eq.dae</uri>
            </mesh>
          </geometry>
        </visual>
        <self_collide>0</self_collide>
        <enable_wind>0</enable_wind>
        <kinematic>0</kinematic>
      </link>
      <joint name='l_wrist_roll_eq_joint' type='revolute'>
        <child>l_wrist_cup_eq_link</child>
        <parent>l_wrist_slider_eq_link</parent>
        <axis>
          <xyz expressed_in='__model__'>1 0 -0</xyz>
          <limit>
            <lower>-0.523599</lower>
            <upper>0.523599</upper>
            <effort>10</effort>
            <velocity>3.14</velocity>
          </limit>
          <dynamics>
            <damping>10</damping>
            <friction>0</friction>
            <spring_reference>0</spring_reference>
            <spring_stiffness>0</spring_stiffness>
          </dynamics>
        </axis>
        <physics>
          <ode>
            <implicit_spring_damper>1</implicit_spring_damper>
            <cfm_damping>1</cfm_damping>
            <limit>
              <cfm>0</cfm>
              <erp>0.2</erp>
            </limit>
          </ode>
        </physics>
      </joint>
      <link name='l_hand_root_link'>
        <pose>-0.04 0.211 0.298 0 -0 0</pose>
        <inertial>
          <pose>0.000191 -0.013614 -0.06234 0 -0 0</pose>
          <mass>0.3</mass>
          <inertia>
            <ixx>0.000294522</ixx>
            <ixy>1.41029e-06</ixy>
            <ixz>6.92026e-08</ixz>
            <iyy>0.000297775</iyy>
            <iyz>-2.11461e-05</iyz>
            <izz>0.000189897</izz>
          </inertia>
        </inertial>
        <collision name='l_hand_root_link_collision'>
          <pose>0.04 -0.211 -0.458 0 -0 0</pose>
          <geometry>
            <mesh>
              <scale>0.001 0.001 0.001</scale>
              <uri>model://cer/meshes/dae/sim_cer_l_hand_root.dae</uri>
            </mesh>
          </geometry>
          <max_contacts>10</max_contacts>
          <surface>
            <contact>
              <ode/>
            </contact>
            <bounce/>
            <friction>
              <torsional>
                <ode/>
              </torsional>
              <ode/>
            </friction>
          </surface>
        </collision>
        <visual name='l_hand_root_link_visual'>
          <pose>0.04 -0.211 -0.458 0 -0 0</pose>
          <geometry>
            <mesh>
              <scale>0.001 0.001 0.001</scale>
              <uri>model://cer/meshes/dae/sim_cer_l_hand_root.dae</uri>
            </mesh>
          </geometry>
        </visual>
        <self_collide>0</self_collide>
        <enable_wind>0</enable_wind>
        <kinematic>0</kinematic>
      </link>
      <joint name='l_wrist_pitch_eq_joint' type='revolute'>
        <child>l_hand_root_link</child>
        <parent>l_wrist_cup_eq_link</parent>
        <axis>
          <xyz expressed_in='__model__'>-0 -1 -0</xyz>
          <limit>
            <lower>-0.523599</lower>
            <upper>0.523599</upper>
            <effort>10</effort>
            <velocity>3.14</velocity>
          </limit>
          <dynamics>
            <damping>10</damping>
            <friction>0</friction>
            <spring_reference>0</spring_reference>
            <spring_stiffness>0</spring_stiffness>
          </dynamics>
        </axis>
        <physics>
          <ode>
            <implicit_spring_damper>1</implicit_spring_damper>
            <cfm_damping>1</cfm_damping>
            <limit>
              <cfm>0</cfm>
              <erp>0.2</erp>
            </limit>
          </ode>
        </physics>
      </joint>
      <link name='l_hand_paddle_proximal_link'>
        <pose>-0.04 0.198143 0.185494 0 -0 0</pose>
        <inertial>
          <pose>-9.7e-05 0.010867 -0.022259 0 -0 0</pose>
          <mass>0.05</mass>
          <inertia>
            <ixx>0.0001</ixx>
            <ixy>-6.9439e-09</ixy>
            <ixz>1.7549e-08</ixz>
            <iyy>0.0001</iyy>
            <iyz>1.81902e-06</iyz>
            <izz>0.0001</izz>
          </inertia>
        </inertial>
        <collision name='l_hand_paddle_proximal_link_collision'>
          <pose>0.04 -0.198143 -0.345494 0 -0 0</pose>
          <geometry>
            <mesh>
              <scale>0.001 0.001 0.001</scale>
              <uri>model://cer/meshes/dae/sim_cer_l_hand_paddle_proximal.dae</uri>
            </mesh>
          </geometry>
          <max_contacts>10</max_contacts>
          <surface>
            <contact>
              <ode/>
            </contact>
            <bounce/>
            <friction>
              <torsional>
                <ode/>
              </torsional>
              <ode/>
            </friction>
          </surface>
        </collision>
        <visual name='l_hand_paddle_proximal_link_visual'>
          <pose>0.04 -0.198143 -0.345494 0 -0 0</pose>
          <geometry>
            <mesh>
              <scale>0.001 0.001 0.001</scale>
              <uri>model://cer/meshes/dae/sim_cer_l_hand_paddle_proximal.dae</uri>
            </mesh>
          </geometry>
        </visual>
        <self_collide>0</self_collide>
        <enable_wind>0</enable_wind>
        <kinematic>0</kinematic>
      </link>
      <joint name='l_hand_paddle_proximal_joint' type='revolute'>
        <child>l_hand_paddle_proximal_link</child>
        <parent>l_hand_root_link</parent>
        <axis>
          <xyz expressed_in='__model__'>-1 -0 0</xyz>
          <limit>
            <lower>0</lower>
            <upper>1.22173</upper>
            <effort>5</effort>
            <velocity>3.14</velocity>
          </limit>
          <dynamics>
            <damping>10</damping>
            <friction>0</friction>
            <spring_reference>0</spring_reference>
            <spring_stiffness>0</spring_stiffness>
          </dynamics>
        </axis>
        <physics>
          <ode>
            <implicit_spring_damper>1</implicit_spring_damper>
            <cfm_damping>1</cfm_damping>
            <limit>
              <cfm>0</cfm>
              <erp>0.2</erp>
            </limit>
          </ode>
        </physics>
      </joint>
      <link name='l_hand_paddle_distal_link'>
        <pose>-0.04 0.214471 0.146748 0 -0 0</pose>
        <inertial>
          <pose>0.001321 0.005592 -0.020601 0 -0 0</pose>
          <mass>0.05</mass>
          <inertia>
            <ixx>0.0001</ixx>
            <ixy>-1.94983e-07</ixy>
            <ixz>9.01259e-07</ixz>
            <iyy>0.0001</iyy>
            <iyz>6.79853e-07</iyz>
            <izz>0.0001</izz>
          </inertia>
        </inertial>
        <collision name='l_hand_paddle_distal_link_collision'>
          <pose>0.04 -0.214471 -0.306748 0 -0 0</pose>
          <geometry>
            <mesh>
              <scale>0.001 0.001 0.001</scale>
              <uri>model://cer/meshes/dae/sim_cer_l_hand_paddle_distal.dae</uri>
            </mesh>
          </geometry>
          <max_contacts>10</max_contacts>
          <surface>
            <contact>
              <ode/>
            </contact>
            <bounce/>
            <friction>
              <torsional>
                <ode/>
              </torsional>
              <ode/>
            </friction>
          </surface>
        </collision>
        <visual name='l_hand_paddle_distal_link_visual'>
          <pose>0.04 -0.214471 -0.306748 0 -0 0</pose>
          <geometry>
            <mesh>
              <scale>0.001 0.001 0.001</scale>
              <uri>model://cer/meshes/dae/sim_cer_l_hand_paddle_distal.dae</uri>
            </mesh>
          </geometry>
        </visual>
        <self_collide>0</self_collide>
        <enable_wind>0</enable_wind>
        <kinematic>0</kinematic>
      </link>
      <joint name='l_hand_paddle_distal_joint' type='revolute'>
        <child>l_hand_paddle_distal_link</child>
        <parent>l_hand_paddle_proximal_link</parent>
        <axis>
          <xyz expressed_in='__model__'>-1 -0 0</xyz>
          <limit>
            <lower>0</lower>
            <upper>1.22173</upper>
            <effort>5</effort>
            <velocity>3.14</velocity>
          </limit>
          <dynamics>
            <damping>10</damping>
            <friction>0</friction>
            <spring_reference>0</spring_reference>
            <spring_stiffness>0</spring_stiffness>
          </dynamics>
        </axis>
        <physics>
          <ode>
            <implicit_spring_damper>1</implicit_spring_damper>
            <cfm_damping>1</cfm_damping>
            <limit>
              <cfm>0</cfm>
              <erp>0.2</erp>
            </limit>
          </ode>
        </physics>
      </joint>
      <link name='l_hand_thumb_proximal_link'>
        <pose>-0.04 0.171352 0.222282 0 -0 0</pose>
        <inertial>
          <pose>0.002515 -0.017936 -0.003159 0 -0 0</pose>
          <mass>0.05</mass>
          <inertia>
            <ixx>0.0001</ixx>
            <ixy>-1.50858e-09</ixy>
            <ixz>3.04948e-10</ixz>
            <iyy>0.0001</iyy>
            <iyz>-2.63475e-06</iyz>
            <izz>0.0001</izz>
          </inertia>
        </inertial>
        <collision name='l_hand_thumb_proximal_link_collision'>
          <pose>0.04 -0.171352 -0.382282 0 -0 0</pose>
          <geometry>
            <mesh>
              <scale>0.001 0.001 0.001</scale>
              <uri>model://cer/meshes/dae/sim_cer_l_hand_thumb_proximal.dae</uri>
            </mesh>
          </geometry>
          <max_contacts>10</max_contacts>
          <surface>
            <contact>
              <ode/>
            </contact>
            <bounce/>
            <friction>
              <torsional>
                <ode/>
              </torsional>
              <ode/>
            </friction>
          </surface>
        </collision>
        <visual name='l_hand_thumb_proximal_link_visual'>
          <pose>0.04 -0.171352 -0.382282 0 -0 0</pose>
          <geometry>
            <mesh>
              <scale>0.001 0.001 0.001</scale>
              <uri>model://cer/meshes/dae/sim_cer_l_hand_thumb_proximal.dae</uri>
            </mesh>
          </geometry>
        </visual>
        <self_collide>0</self_collide>
        <enable_wind>0</enable_wind>
        <kinematic>0</kinematic>
      </link>
      <joint name='l_hand_thumb_proximal_joint' type='revolute'>
        <child>l_hand_thumb_proximal_link</child>
        <parent>l_hand_root_link</parent>
        <axis>
          <xyz expressed_in='__model__'>1 0 -0</xyz>
          <limit>
            <lower>0</lower>
            <upper>1.0472</upper>
            <effort>5</effort>
            <velocity>3.14</velocity>
          </limit>
          <dynamics>
            <damping>10</damping>
            <friction>0</friction>
            <spring_reference>0</spring_reference>
            <spring_stiffness>0</spring_stiffness>
          </dynamics>
        </axis>
        <physics>
          <ode>
            <implicit_spring_damper>1</implicit_spring_damper>
            <cfm_damping>1</cfm_damping>
            <limit>
              <cfm>0</cfm>
              <erp>0.2</erp>
            </limit>
          </ode>
        </physics>
      </joint>
      <link name='l_hand_thumb_distal_link'>
        <pose>-0.039745 0.130827 0.211296 0 -0 0</pose>
        <inertial>
          <pose>0.002193 -0.014529 -0.005865 0 -0 0</pose>
          <mass>0.05</mass>
          <inertia>
            <ixx>0.0001</ixx>
            <ixy>1.50893e-10</ixy>
            <ixz>4.0488e-10</ixz>
            <iyy>0.0001</iyy>
            <iyz>-9.14021e-07</iyz>
            <izz>0.0001</izz>
          </inertia>
        </inertial>
        <collision name='l_hand_thumb_distal_link_collision'>
          <pose>0.039745 -0.130827 -0.371296 0 -0 0</pose>
          <geometry>
            <mesh>
              <scale>0.001 0.001 0.001</scale>
              <uri>model://cer/meshes/dae/sim_cer_l_hand_thumb_distal.dae</uri>
            </mesh>
          </geometry>
          <max_contacts>10</max_contacts>
          <surface>
            <contact>
              <ode/>
            </contact>
            <bounce/>
            <friction>
              <torsional>
                <ode/>
              </torsional>
              <ode/>
            </friction>
          </surface>
        </collision>
        <visual name='l_hand_thumb_distal_link_visual'>
          <pose>0.039745 -0.130827 -0.371296 0 -0 0</pose>
          <geometry>
            <mesh>
              <scale>0.001 0.001 0.001</scale>
              <uri>model://cer/meshes/dae/sim_cer_l_hand_thumb_distal.dae</uri>
            </mesh>
          </geometry>
        </visual>
        <self_collide>0</self_collide>
        <enable_wind>0</enable_wind>
        <kinematic>0</kinematic>
      </link>
      <joint name='l_hand_thumb_distal_joint' type='revolute'>
        <child>l_hand_thumb_distal_link</child>
        <parent>l_hand_thumb_proximal_link</parent>
        <axis>
          <xyz expressed_in='__model__'>1 0 -0</xyz>
          <limit>
            <lower>0</lower>
            <upper>1.22173</upper>
            <effort>5</effort>
            <velocity>3.14</velocity>
          </limit>
          <dynamics>
            <damping>10</damping>
            <friction>0</friction>
            <spring_reference>0</spring_reference>
            <spring_stiffness>0</spring_stiffness>
          </dynamics>
        </axis>
        <physics>
          <ode>
            <implicit_spring_damper>1</implicit_spring_damper>
            <cfm_damping>1</cfm_damping>
            <limit>
              <cfm>0</cfm>
              <erp>0.2</erp>
            </limit>
          </ode>
        </physics>
      </joint>
      <link name='neck_link'>
        <pose>-0.05 -0 0.87 0 -0 0</pose>
        <inertial>
          <pose>-0.000322 0 0.07756 0 -0 0</pose>
          <mass>1.4</mass>
          <inertia>
            <ixx>0.00429793</ixx>
            <ixy>0</ixy>
            <ixz>-0.000592817</ixz>
            <iyy>0.00443784</iyy>
            <iyz>-6.85477e-08</iyz>
            <izz>0.000419904</izz>
          </inertia>
        </inertial>
        <collision name='neck_link_collision'>
          <pose>0.05 0 -1.03 0 -0 0</pose>
          <geometry>
            <mesh>
              <scale>0.001 0.001 0.001</scale>
              <uri>model://cer/meshes/dae/sim_cer_neck.dae</uri>
            </mesh>
          </geometry>
          <max_contacts>10</max_contacts>
          <surface>
            <contact>
              <ode/>
            </contact>
            <bounce/>
            <friction>
              <torsional>
                <ode/>
              </torsional>
              <ode/>
            </friction>
          </surface>
        </collision>
        <visual name='neck_link_visual'>
          <pose>0.05 0 -1.03 0 -0 0</pose>
          <geometry>
            <mesh>
              <scale>0.001 0.001 0.001</scale>
              <uri>model://cer/meshes/dae/sim_cer_neck.dae</uri>
            </mesh>
          </geometry>
        </visual>
        <self_collide>0</self_collide>
        <enable_wind>0</enable_wind>
        <kinematic>0</kinematic>
      </link>
      <joint name='neck_pitch_joint' type='revolute'>
        <child>neck_link</child>
        <parent>chest_link</parent>
        <axis>
          <xyz expressed_in='__model__'>0 1 0</xyz>
          <limit>
            <lower>-0.523599</lower>
            <upper>0.872665</upper>
            <effort>10</effort>
            <velocity>3.14</velocity>
          </limit>
          <dynamics>
            <damping>10</damping>
            <friction>0</friction>
            <spring_reference>0</spring_reference>
            <spring_stiffness>0</spring_stiffness>
          </dynamics>
        </axis>
        <physics>
          <ode>
            <implicit_spring_damper>1</implicit_spring_damper>
            <cfm_damping>1</cfm_damping>
            <limit>
              <cfm>0</cfm>
              <erp>0.2</erp>
            </limit>
          </ode>
        </physics>
      </joint>
      <link name='head_link'>
        <pose>-0.038321 -0 1.02838 0 -0 0</pose>
        <inertial>
          <pose>0.030149 -2e-06 -0.00035 0 -0 0</pose>
          <mass>2</mass>
          <inertia>
            <ixx>0.0106536</ixx>
            <ixy>-7.34817e-08</ixy>
            <ixz>0.000274098</ixz>
            <iyy>0.00398482</iyy>
            <iyz>1.64063e-07</iyz>
            <izz>0.00944369</izz>
          </inertia>
        </inertial>
        <collision name='head_link_collision'>
          <pose>0.038321 0 -1.18838 0 -0 0</pose>
          <geometry>
            <mesh>
              <scale>0.001 0.001 0.001</scale>
              <uri>model://cer/meshes/dae/sim_cer_head.dae</uri>
            </mesh>
          </geometry>
          <surface>
            <contact>
              <ode/>
            </contact>
            <friction>
              <ode/>
              <torsional>
                <ode/>
              </torsional>
            </friction>
            <bounce/>
          </surface>
          <max_contacts>10</max_contacts>
        </collision>
        <visual name='head_link_visual'>
          <pose>0.038321 0 -1.18838 0 -0 0</pose>
          <geometry>
            <mesh>
              <scale>0.001 0.001 0.001</scale>
              <uri>model://cer/meshes/dae/sim_cer_head.dae</uri>
            </mesh>
          </geometry>
          <material>
            <diffuse>1 1 1 1</diffuse>
            <script>
              <uri>__default__</uri>
              <name>__default__</name>
            </script>
          </material>
          <plugin name='face' filename='libgazebo_yarp_videotexture.so'>
            <yarpConfigurationFile>model://cer/conf/gazebo_cer_face.ini</yarpConfigurationFile>
          </plugin>
        </visual>
        <velocity_decay/>
        <sensor name='multicamera_sensor' type='multicamera'>
          <always_on>1</always_on>
          <update_rate>30</update_rate>
          <pose>0.052167 0 -0.06748 -1.5708 -0 -1.5708</pose>
          <camera name='left_camera'>
            <pose>-0.0325 0 0 -1.57079 -1.57079 3.14159</pose>
            <horizontal_fov>1.5708</horizontal_fov>
            <image>
              <width>640</width>
              <height>480</height>
            </image>
            <clip>
              <near>0.1</near>
              <far>100</far>
            </clip>
          </camera>
          <camera name='right_camera'>
            <pose>0.0325 0 0 -1.57079 -1.57079 3.14159</pose>
            <horizontal_fov>1.5708</horizontal_fov>
            <image>
              <width>640</width>
              <height>480</height>
            </image>
            <clip>
              <near>0.1</near>
              <far>100</far>
            </clip>
          </camera>
          <plugin name='multicamera_plugin' filename='libgazebo_yarp_multicamera.so'>
            <yarpConfigurationFile>model://cer/conf/gazebo_cer_multicamera.ini</yarpConfigurationFile>
          </plugin>
        </sensor>
        <velocity_decay/>
        <sensor name='asus_xtion_depth' type='depth'>
          <always_on>1</always_on>
          <update_rate>30</update_rate>
          <pose>0.059881 0.044487 0.04402 -1.5708 -0 -1.5708</pose>
          <camera name='asus_xtion_depth_camera'>
            <pose>0 0 0 -1.57079 -1.57079 3.14159</pose>
            <horizontal_fov>1.02259</horizontal_fov>
            <distortion>
              <k1>0</k1>
              <k2>0</k2>
              <k3>0</k3>
              <p1>0</p1>
              <p2>0</p2>
              <center>319.5 239.5</center>
            </distortion>
            <image>
              <width>640</width>
              <height>480</height>
              <format>R8G8B8</format>
            </image>
            <clip>
              <near>0.02</near>
              <far>3000</far>
            </clip>
          </camera>
          <plugin name='depth_camera_plugin' filename='libgazebo_yarp_depthCamera.so'>
            <yarpConfigurationFile>model://cer/conf/gazebo_cer_depthCamera.ini</yarpConfigurationFile>
          </plugin>
        </sensor>
        <gravity>1</gravity>
        <velocity_decay/>
        <sensor name='asus_xtion_rgb' type='camera'>
          <always_on>1</always_on>
          <update_rate>30</update_rate>
          <pose>0.059881 0.018487 0.04402 -1.5708 -0 -1.5708</pose>
          <camera name='asus_xtion_rgb_camera'>
            <pose>0 0 0 -1.57079 -1.57079 3.14159</pose>
            <horizontal_fov>1.02259</horizontal_fov>
            <distortion>
              <k1>0</k1>
              <k2>0</k2>
              <k3>0</k3>
              <p1>0</p1>
              <p2>0</p2>
              <center>319.5 239.5</center>
            </distortion>
            <image>
              <width>640</width>
              <height>480</height>
              <format>R8G8B8</format>
            </image>
            <clip>
              <near>0.02</near>
              <far>3000</far>
            </clip>
          </camera>
          <plugin name='xtion_camera_rgb_plugin' filename='libgazebo_yarp_camera.so'>
            <yarpConfigurationFile>model://cer/conf/gazebo_cer_xtion_camera_rgb.ini</yarpConfigurationFile>
          </plugin>
        </sensor>
        <self_collide>0</self_collide>
        <enable_wind>0</enable_wind>
        <kinematic>0</kinematic>
      </link>
      <joint name='neck_yaw_joint' type='revolute'>
        <child>head_link</child>
        <parent>neck_link</parent>
        <axis>
          <xyz expressed_in='__model__'>0.173648 -0 0.984808</xyz>
          <limit>
            <lower>-1.39626</lower>
            <upper>1.39626</upper>
            <effort>10</effort>
            <velocity>3.14</velocity>
          </limit>
          <dynamics>
            <damping>10</damping>
            <friction>0</friction>
            <spring_reference>0</spring_reference>
            <spring_stiffness>0</spring_stiffness>
          </dynamics>
        </axis>
        <physics>
          <ode>
            <implicit_spring_damper>1</implicit_spring_damper>
            <cfm_damping>1</cfm_damping>
            <limit>
              <cfm>0</cfm>
              <erp>0.2</erp>
            </limit>
          </ode>
        </physics>
      </joint>
      <link name='r_clavicle_link'>
        <pose>-0.04 -0.177 0.84 0 -0 0</pose>
        <inertial>
          <pose>0 0 0 0 -0 0</pose>
          <mass>0.2</mass>
          <inertia>
            <ixx>0.000288</ixx>
            <ixy>0</ixy>
            <ixz>0</ixz>
            <iyy>0.000288</iyy>
            <iyz>0</iyz>
            <izz>0.000288</izz>
          </inertia>
        </inertial>
        <collision name='r_clavicle_link_collision'>
          <pose>0.04 0.177 -1 0 -0 0</pose>
          <geometry>
            <mesh>
              <scale>0.001 0.001 0.001</scale>
              <uri>model://cer/meshes/dae/sim_cer_r_clavicle.dae</uri>
            </mesh>
          </geometry>
          <max_contacts>10</max_contacts>
          <surface>
            <contact>
              <ode/>
            </contact>
            <bounce/>
            <friction>
              <torsional>
                <ode/>
              </torsional>
              <ode/>
            </friction>
          </surface>
        </collision>
        <visual name='r_clavicle_link_visual'>
          <pose>0.04 0.177 -1 0 -0 0</pose>
          <geometry>
            <mesh>
              <scale>0.001 0.001 0.001</scale>
              <uri>model://cer/meshes/dae/sim_cer_r_clavicle.dae</uri>
            </mesh>
          </geometry>
        </visual>
        <self_collide>0</self_collide>
        <enable_wind>0</enable_wind>
        <kinematic>0</kinematic>
      </link>
      <joint name='r_shoulder_pitch_joint' type='revolute'>
        <child>r_clavicle_link</child>
        <parent>chest_link</parent>
        <axis>
          <xyz expressed_in='__model__'>-0 -0.970296 0.241922</xyz>
          <limit>
            <lower>-0.523599</lower>
            <upper>1.5708</upper>
            <effort>30</effort>
            <velocity>3.14</velocity>
          </limit>
          <dynamics>
            <damping>10</damping>
            <friction>0</friction>
            <spring_reference>0</spring_reference>
            <spring_stiffness>0</spring_stiffness>
          </dynamics>
        </axis>
        <physics>
          <ode>
            <implicit_spring_damper>1</implicit_spring_damper>
            <cfm_damping>1</cfm_damping>
            <limit>
              <cfm>0</cfm>
              <erp>0.2</erp>
            </limit>
          </ode>
        </physics>
      </joint>
      <link name='r_shoulder_link'>
        <pose>-0.04 -0.177 0.84 0 -0 0</pose>
        <inertial>
          <pose>2e-06 -0.042148 -0.06332 0 -0 0</pose>
          <mass>0.5</mass>
          <inertia>
            <ixx>0.00076143</ixx>
            <ixy>0</ixy>
            <ixz>-2.84508e-08</ixz>
            <iyy>0.000819748</iyy>
            <iyz>0.000135828</iyz>
            <izz>0.000588486</izz>
          </inertia>
        </inertial>
        <collision name='r_shoulder_link_collision'>
          <pose>0.04 0.177 -1 0 -0 0</pose>
          <geometry>
            <mesh>
              <scale>0.001 0.001 0.001</scale>
              <uri>model://cer/meshes/dae/sim_cer_r_shoulder.dae</uri>
            </mesh>
          </geometry>
          <max_contacts>10</max_contacts>
          <surface>
            <contact>
              <ode/>
            </contact>
            <bounce/>
            <friction>
              <torsional>
                <ode/>
              </torsional>
              <ode/>
            </friction>
          </surface>
        </collision>
        <visual name='r_shoulder_link_visual'>
          <pose>0.04 0.177 -1 0 -0 0</pose>
          <geometry>
            <mesh>
              <scale>0.001 0.001 0.001</scale>
              <uri>model://cer/meshes/dae/sim_cer_r_shoulder.dae</uri>
            </mesh>
          </geometry>
        </visual>
        <self_collide>0</self_collide>
        <enable_wind>0</enable_wind>
        <kinematic>0</kinematic>
      </link>
      <joint name='r_shoulder_roll_joint' type='revolute'>
        <child>r_shoulder_link</child>
        <parent>r_clavicle_link</parent>
        <axis>
          <xyz expressed_in='__model__'>-1 0 0</xyz>
          <limit>
            <lower>-0.174533</lower>
            <upper>1.309</upper>
            <effort>30</effort>
            <velocity>3.14</velocity>
          </limit>
          <dynamics>
            <damping>10</damping>
            <friction>0</friction>
            <spring_reference>0</spring_reference>
            <spring_stiffness>0</spring_stiffness>
          </dynamics>
        </axis>
        <physics>
          <ode>
            <implicit_spring_damper>1</implicit_spring_damper>
            <cfm_damping>1</cfm_damping>
            <limit>
              <cfm>0</cfm>
              <erp>0.2</erp>
            </limit>
          </ode>
        </physics>
      </joint>
      <link name='r_upperarm_FT_sensor_link'>
        <pose>-0.04 -0.211 0.73 0 -0 0</pose>
        <inertial>
          <pose>-0.000784 0.000123 -0.042763 0 -0 0</pose>
          <mass>0.8</mass>
          <inertia>
            <ixx>0.0012924</ixx>
            <ixy>4.63196e-08</ixy>
            <ixz>-4.45409e-05</ixz>
            <iyy>0.00128408</iyy>
            <iyz>1.2212e-06</iyz>
            <izz>0.000657768</izz>
          </inertia>
        </inertial>
        <collision name='r_upperarm_FT_sensor_link_collision'>
          <pose>0.04 0.211 -0.89 0 -0 0</pose>
          <geometry>
            <mesh>
              <scale>0.001 0.001 0.001</scale>
              <uri>model://cer/meshes/dae/sim_cer_r_upperarm_sensor.dae</uri>
            </mesh>
          </geometry>
          <max_contacts>10</max_contacts>
          <surface>
            <contact>
              <ode/>
            </contact>
            <bounce/>
            <friction>
              <torsional>
                <ode/>
              </torsional>
              <ode/>
            </friction>
          </surface>
        </collision>
        <collision name='r_upperarm_FT_sensor_link_fixed_joint_lump__r_upperarm_link_collision_1'>
          <pose>0.04 0.211 -0.89 0 -0 0</pose>
          <geometry>
            <mesh>
              <scale>0.001 0.001 0.001</scale>
              <uri>model://cer/meshes/dae/sim_cer_r_upperarm.dae</uri>
            </mesh>
          </geometry>
          <max_contacts>10</max_contacts>
          <surface>
            <contact>
              <ode/>
            </contact>
            <bounce/>
            <friction>
              <torsional>
                <ode/>
              </torsional>
              <ode/>
            </friction>
          </surface>
        </collision>
        <visual name='r_upperarm_FT_sensor_link_visual'>
          <pose>0.04 0.211 -0.89 0 -0 0</pose>
          <geometry>
            <mesh>
              <scale>0.001 0.001 0.001</scale>
              <uri>model://cer/meshes/dae/sim_cer_r_upperarm_sensor.dae</uri>
            </mesh>
          </geometry>
        </visual>
        <visual name='r_upperarm_FT_sensor_link_fixed_joint_lump__r_upperarm_link_visual_1'>
          <pose>0.04 0.211 -0.89 0 -0 0</pose>
          <geometry>
            <mesh>
              <scale>0.001 0.001 0.001</scale>
              <uri>model://cer/meshes/dae/sim_cer_r_upperarm.dae</uri>
            </mesh>
          </geometry>
        </visual>
        <self_collide>0</self_collide>
        <enable_wind>0</enable_wind>
        <kinematic>0</kinematic>
      </link>
      <joint name='r_shoulder_yaw_joint' type='revolute'>
        <child>r_upperarm_FT_sensor_link</child>
        <parent>r_shoulder_link</parent>
        <axis>
          <xyz expressed_in='__model__'>0 0 -1</xyz>
          <limit>
            <lower>-1.5708</lower>
            <upper>1.5708</upper>
            <effort>15</effort>
            <velocity>3.14</velocity>
          </limit>
          <dynamics>
            <damping>10</damping>
            <friction>0</friction>
            <spring_reference>0</spring_reference>
            <spring_stiffness>0</spring_stiffness>
          </dynamics>
        </axis>
        <physics>
          <ode>
            <implicit_spring_damper>1</implicit_spring_damper>
            <cfm_damping>1</cfm_damping>
            <limit>
              <cfm>0</cfm>
              <erp>0.2</erp>
            </limit>
          </ode>
        </physics>
      </joint>
      <link name='r_elbow_sphere_link'>
        <pose>-0.04 -0.211 0.589 0 -0 0</pose>
        <inertial>
          <pose>0 0 0 0 -0 0</pose>
          <mass>0.2</mass>
          <inertia>
            <ixx>0.000128</ixx>
            <ixy>0</ixy>
            <ixz>0</ixz>
            <iyy>0.000128</iyy>
            <iyz>0</iyz>
            <izz>0.000128</izz>
          </inertia>
        </inertial>
        <collision name='r_elbow_sphere_link_collision'>
          <pose>0.04 0.211 -0.749 0 -0 0</pose>
          <geometry>
            <mesh>
              <scale>0.001 0.001 0.001</scale>
              <uri>model://cer/meshes/dae/sim_cer_r_elbow_sphere.dae</uri>
            </mesh>
          </geometry>
          <max_contacts>10</max_contacts>
          <surface>
            <contact>
              <ode/>
            </contact>
            <bounce/>
            <friction>
              <torsional>
                <ode/>
              </torsional>
              <ode/>
            </friction>
          </surface>
        </collision>
        <visual name='r_elbow_sphere_link_visual'>
          <pose>0.04 0.211 -0.749 0 -0 0</pose>
          <geometry>
            <mesh>
              <scale>0.001 0.001 0.001</scale>
              <uri>model://cer/meshes/dae/sim_cer_r_elbow_sphere.dae</uri>
            </mesh>
          </geometry>
        </visual>
        <self_collide>0</self_collide>
        <enable_wind>0</enable_wind>
        <kinematic>0</kinematic>
      </link>
      <joint name='r_elbow_joint' type='revolute'>
        <child>r_elbow_sphere_link</child>
        <parent>r_upperarm_FT_sensor_link</parent>
        <axis>
          <xyz expressed_in='__model__'>-0 -1 -0</xyz>
          <limit>
            <lower>0</lower>
            <upper>1.74533</upper>
            <effort>20</effort>
            <velocity>3.14</velocity>
          </limit>
          <dynamics>
            <damping>10</damping>
            <friction>0</friction>
            <spring_reference>0</spring_reference>
            <spring_stiffness>0</spring_stiffness>
          </dynamics>
        </axis>
        <physics>
          <ode>
            <implicit_spring_damper>1</implicit_spring_damper>
            <cfm_damping>1</cfm_damping>
            <limit>
              <cfm>0</cfm>
              <erp>0.2</erp>
            </limit>
          </ode>
        </physics>
      </joint>
      <link name='r_forearm_link'>
        <pose>-0.04 -0.211 0.518 0 -0 0</pose>
        <inertial>
          <pose>-0.000512 0.000175 -0.072511 0 -0 0</pose>
          <mass>0.6</mass>
          <inertia>
            <ixx>0.00283352</ixx>
            <ixy>0</ixy>
            <ixz>3.15449e-05</ixz>
            <iyy>0.00282953</iyy>
            <iyz>-1.03787e-07</iyz>
            <izz>0.000436673</izz>
          </inertia>
        </inertial>
        <collision name='r_forearm_link_collision'>
          <pose>0.04 0.211 -0.678 0 -0 0</pose>
          <geometry>
            <mesh>
              <scale>0.001 0.001 0.001</scale>
              <uri>model://cer/meshes/dae/sim_cer_r_forearm.dae</uri>
            </mesh>
          </geometry>
          <max_contacts>10</max_contacts>
          <surface>
            <contact>
              <ode/>
            </contact>
            <bounce/>
            <friction>
              <torsional>
                <ode/>
              </torsional>
              <ode/>
            </friction>
          </surface>
        </collision>
        <visual name='r_forearm_link_visual'>
          <pose>0.04 0.211 -0.678 0 -0 0</pose>
          <geometry>
            <mesh>
              <scale>0.001 0.001 0.001</scale>
              <uri>model://cer/meshes/dae/sim_cer_r_forearm.dae</uri>
            </mesh>
          </geometry>
        </visual>
        <self_collide>0</self_collide>
        <enable_wind>0</enable_wind>
        <kinematic>0</kinematic>
      </link>
      <joint name='r_wrist_pronosupination_joint' type='revolute'>
        <child>r_forearm_link</child>
        <parent>r_elbow_sphere_link</parent>
        <axis>
          <xyz expressed_in='__model__'>-0 0 -1</xyz>
          <limit>
            <lower>-1.5708</lower>
            <upper>1.5708</upper>
            <effort>10</effort>
            <velocity>3.14</velocity>
          </limit>
          <dynamics>
            <damping>10</damping>
            <friction>0</friction>
            <spring_reference>0</spring_reference>
            <spring_stiffness>0</spring_stiffness>
          </dynamics>
        </axis>
        <physics>
          <ode>
            <implicit_spring_damper>1</implicit_spring_damper>
            <cfm_damping>1</cfm_damping>
            <limit>
              <cfm>0</cfm>
              <erp>0.2</erp>
            </limit>
          </ode>
        </physics>
      </joint>
      <link name='r_wrist_slider_eq_link'>
        <pose>-0.04 -0.211 0.589 0 -0 0</pose>
        <inertial>
          <pose>0 5.9e-05 -0.225759 0 -0 0</pose>
          <mass>0.3</mass>
          <inertia>
            <ixx>0.00094001</ixx>
            <ixy>0</ixy>
            <ixz>0</ixz>
            <iyy>0.000940012</iyy>
            <iyz>0</iyz>
            <izz>0.00022094</izz>
          </inertia>
        </inertial>
        <collision name='r_wrist_slider_eq_link_collision'>
          <pose>0.04 0.211 -0.749 0 -0 0</pose>
          <geometry>
            <mesh>
              <scale>0.001 0.001 0.001</scale>
              <uri>model://cer/meshes/dae/sim_cer_r_wrist_slider.dae</uri>
            </mesh>
          </geometry>
          <max_contacts>10</max_contacts>
          <surface>
            <contact>
              <ode/>
            </contact>
            <bounce/>
            <friction>
              <torsional>
                <ode/>
              </torsional>
              <ode/>
            </friction>
          </surface>
        </collision>
        <visual name='r_wrist_slider_eq_link_visual'>
          <pose>0.04 0.211 -0.749 0 -0 0</pose>
          <geometry>
            <mesh>
              <scale>0.001 0.001 0.001</scale>
              <uri>model://cer/meshes/dae/sim_cer_r_wrist_slider.dae</uri>
            </mesh>
          </geometry>
        </visual>
        <self_collide>0</self_collide>
        <enable_wind>0</enable_wind>
        <kinematic>0</kinematic>
      </link>
      <joint name='r_wrist_heave_eq_joint' type='prismatic'>
        <child>r_wrist_slider_eq_link</child>
        <parent>r_forearm_link</parent>
        <axis>
          <xyz expressed_in='__model__'>-0 0 -1</xyz>
          <limit>
            <lower>0</lower>
            <upper>0.13</upper>
            <effort>200</effort>
            <velocity>0.25</velocity>
          </limit>
          <dynamics>
            <damping>100</damping>
            <friction>0</friction>
            <spring_reference>0</spring_reference>
            <spring_stiffness>0</spring_stiffness>
          </dynamics>
        </axis>
        <physics>
          <ode>
            <implicit_spring_damper>1</implicit_spring_damper>
            <cfm_damping>1</cfm_damping>
            <limit>
              <cfm>0</cfm>
              <erp>0.2</erp>
            </limit>
          </ode>
        </physics>
      </joint>
      <link name='r_wrist_cup_eq_link'>
        <pose>-0.072 -0.211 0.298 0 -0 1.5708</pose>
        <inertial>
          <pose>-1.1e-05 -0.031941 -0.018146 0 -0 0</pose>
          <mass>0.2</mass>
          <inertia>
            <ixx>0.000102239</ixx>
            <ixy>0</ixy>
            <ixz>3.78925e-08</ixz>
            <iyy>0.000102239</iyy>
            <iyz>0</iyz>
            <izz>0.000163555</izz>
          </inertia>
        </inertial>
        <collision name='r_wrist_cup_eq_link_collision'>
          <pose>0.04 0.179 -0.458 0 -0 0</pose>
          <geometry>
            <mesh>
              <scale>0.001 0.001 0.001</scale>
              <uri>model://cer/meshes/dae/sim_cer_r_wrist_cup_eq.dae</uri>
            </mesh>
          </geometry>
          <max_contacts>10</max_contacts>
          <surface>
            <contact>
              <ode/>
            </contact>
            <bounce/>
            <friction>
              <torsional>
                <ode/>
              </torsional>
              <ode/>
            </friction>
          </surface>
        </collision>
        <visual name='r_wrist_cup_eq_link_visual'>
          <pose>0.04 0.179 -0.458 0 -0 0</pose>
          <geometry>
            <mesh>
              <scale>0.001 0.001 0.001</scale>
              <uri>model://cer/meshes/dae/sim_cer_r_wrist_cup_eq.dae</uri>
            </mesh>
          </geometry>
        </visual>
        <self_collide>0</self_collide>
        <enable_wind>0</enable_wind>
        <kinematic>0</kinematic>
      </link>
      <joint name='r_wrist_roll_eq_joint' type='revolute'>
        <child>r_wrist_cup_eq_link</child>
        <parent>r_wrist_slider_eq_link</parent>
        <axis>
          <xyz expressed_in='__model__'>-1 0 0</xyz>
          <limit>
            <lower>-0.523599</lower>
            <upper>0.523599</upper>
            <effort>10</effort>
            <velocity>3.14</velocity>
          </limit>
          <dynamics>
            <damping>10</damping>
            <friction>0</friction>
            <spring_reference>0</spring_reference>
            <spring_stiffness>0</spring_stiffness>
          </dynamics>
        </axis>
        <physics>
          <ode>
            <implicit_spring_damper>1</implicit_spring_damper>
            <cfm_damping>1</cfm_damping>
            <limit>
              <cfm>0</cfm>
              <erp>0.2</erp>
            </limit>
          </ode>
        </physics>
      </joint>
      <link name='r_hand_root_link'>
        <pose>-0.04 -0.211 0.298 0 -0 0</pose>
        <inertial>
          <pose>0.000191 0.013614 -0.06234 0 -0 0</pose>
          <mass>0.3</mass>
          <inertia>
            <ixx>0.000294522</ixx>
            <ixy>-1.41036e-06</ixy>
            <ixz>6.91732e-08</ixz>
            <iyy>0.000297774</iyy>
            <iyz>2.11461e-05</iyz>
            <izz>0.000189897</izz>
          </inertia>
        </inertial>
        <collision name='r_hand_root_link_collision'>
          <pose>0.04 0.211 -0.458 0 -0 0</pose>
          <geometry>
            <mesh>
              <scale>0.001 0.001 0.001</scale>
              <uri>model://cer/meshes/dae/sim_cer_r_hand_root.dae</uri>
            </mesh>
          </geometry>
          <max_contacts>10</max_contacts>
          <surface>
            <contact>
              <ode/>
            </contact>
            <bounce/>
            <friction>
              <torsional>
                <ode/>
              </torsional>
              <ode/>
            </friction>
          </surface>
        </collision>
        <visual name='r_hand_root_link_visual'>
          <pose>0.04 0.211 -0.458 0 -0 0</pose>
          <geometry>
            <mesh>
              <scale>0.001 0.001 0.001</scale>
              <uri>model://cer/meshes/dae/sim_cer_r_hand_root.dae</uri>
            </mesh>
          </geometry>
        </visual>
        <self_collide>0</self_collide>
        <enable_wind>0</enable_wind>
        <kinematic>0</kinematic>
      </link>
      <joint name='r_wrist_pitch_eq_joint' type='revolute'>
        <child>r_hand_root_link</child>
        <parent>r_wrist_cup_eq_link</parent>
        <axis>
          <xyz expressed_in='__model__'>-0 -1 -0</xyz>
          <limit>
            <lower>-0.523599</lower>
            <upper>0.523599</upper>
            <effort>10</effort>
            <velocity>3.14</velocity>
          </limit>
          <dynamics>
            <damping>10</damping>
            <friction>0</friction>
            <spring_reference>0</spring_reference>
            <spring_stiffness>0</spring_stiffness>
          </dynamics>
        </axis>
        <physics>
          <ode>
            <implicit_spring_damper>1</implicit_spring_damper>
            <cfm_damping>1</cfm_damping>
            <limit>
              <cfm>0</cfm>
              <erp>0.2</erp>
            </limit>
          </ode>
        </physics>
      </joint>
      <link name='r_hand_paddle_proximal_link'>
        <pose>-0.04 -0.198143 0.185494 0 -0 0</pose>
        <inertial>
          <pose>-9.7e-05 -0.010867 -0.022258 0 -0 0</pose>
          <mass>0.05</mass>
          <inertia>
            <ixx>0.0001</ixx>
            <ixy>6.93652e-09</ixy>
            <ixz>1.75564e-08</ixz>
            <iyy>0.0001</iyy>
            <iyz>-1.81901e-06</iyz>
            <izz>0.0001</izz>
          </inertia>
        </inertial>
        <collision name='r_hand_paddle_proximal_link_collision'>
          <pose>0.04 0.198143 -0.345494 0 -0 0</pose>
          <geometry>
            <mesh>
              <scale>0.001 0.001 0.001</scale>
              <uri>model://cer/meshes/dae/sim_cer_r_hand_paddle_proximal.dae</uri>
            </mesh>
          </geometry>
          <max_contacts>10</max_contacts>
          <surface>
            <contact>
              <ode/>
            </contact>
            <bounce/>
            <friction>
              <torsional>
                <ode/>
              </torsional>
              <ode/>
            </friction>
          </surface>
        </collision>
        <visual name='r_hand_paddle_proximal_link_visual'>
          <pose>0.04 0.198143 -0.345494 0 -0 0</pose>
          <geometry>
            <mesh>
              <scale>0.001 0.001 0.001</scale>
              <uri>model://cer/meshes/dae/sim_cer_r_hand_paddle_proximal.dae</uri>
            </mesh>
          </geometry>
        </visual>
        <self_collide>0</self_collide>
        <enable_wind>0</enable_wind>
        <kinematic>0</kinematic>
      </link>
      <joint name='r_hand_paddle_proximal_joint' type='revolute'>
        <child>r_hand_paddle_proximal_link</child>
        <parent>r_hand_root_link</parent>
        <axis>
          <xyz expressed_in='__model__'>1 0 -0</xyz>
          <limit>
            <lower>0</lower>
            <upper>1.22173</upper>
            <effort>5</effort>
            <velocity>3.14</velocity>
          </limit>
          <dynamics>
            <damping>10</damping>
            <friction>0</friction>
            <spring_reference>0</spring_reference>
            <spring_stiffness>0</spring_stiffness>
          </dynamics>
        </axis>
        <physics>
          <ode>
            <implicit_spring_damper>1</implicit_spring_damper>
            <cfm_damping>1</cfm_damping>
            <limit>
              <cfm>0</cfm>
              <erp>0.2</erp>
            </limit>
          </ode>
        </physics>
      </joint>
      <link name='r_hand_paddle_distal_link'>
        <pose>-0.04 -0.214471 0.146748 0 -0 0</pose>
        <inertial>
          <pose>0.001321 -0.005592 -0.020601 0 -0 0</pose>
          <mass>0.05</mass>
          <inertia>
            <ixx>0.0001</ixx>
            <ixy>1.94983e-07</ixy>
            <ixz>9.0126e-07</ixz>
            <iyy>0.0001</iyy>
            <iyz>-6.79853e-07</iyz>
            <izz>0.0001</izz>
          </inertia>
        </inertial>
        <collision name='r_hand_paddle_distal_link_collision'>
          <pose>0.04 0.214471 -0.306748 0 -0 0</pose>
          <geometry>
            <mesh>
              <scale>0.001 0.001 0.001</scale>
              <uri>model://cer/meshes/dae/sim_cer_r_hand_paddle_distal.dae</uri>
            </mesh>
          </geometry>
          <max_contacts>10</max_contacts>
          <surface>
            <contact>
              <ode/>
            </contact>
            <bounce/>
            <friction>
              <torsional>
                <ode/>
              </torsional>
              <ode/>
            </friction>
          </surface>
        </collision>
        <visual name='r_hand_paddle_distal_link_visual'>
          <pose>0.04 0.214471 -0.306748 0 -0 0</pose>
          <geometry>
            <mesh>
              <scale>0.001 0.001 0.001</scale>
              <uri>model://cer/meshes/dae/sim_cer_r_hand_paddle_distal.dae</uri>
            </mesh>
          </geometry>
        </visual>
        <self_collide>0</self_collide>
        <enable_wind>0</enable_wind>
        <kinematic>0</kinematic>
      </link>
      <joint name='r_hand_paddle_distal_joint' type='revolute'>
        <child>r_hand_paddle_distal_link</child>
        <parent>r_hand_paddle_proximal_link</parent>
        <axis>
          <xyz expressed_in='__model__'>1 0 -0</xyz>
          <limit>
            <lower>0</lower>
            <upper>1.22173</upper>
            <effort>5</effort>
            <velocity>3.14</velocity>
          </limit>
          <dynamics>
            <damping>10</damping>
            <friction>0</friction>
            <spring_reference>0</spring_reference>
            <spring_stiffness>0</spring_stiffness>
          </dynamics>
        </axis>
        <physics>
          <ode>
            <implicit_spring_damper>1</implicit_spring_damper>
            <cfm_damping>1</cfm_damping>
            <limit>
              <cfm>0</cfm>
              <erp>0.2</erp>
            </limit>
          </ode>
        </physics>
      </joint>
      <link name='r_hand_thumb_proximal_link'>
        <pose>-0.04 -0.171352 0.222282 0 -0 0</pose>
        <inertial>
          <pose>0.002515 0.017936 -0.003159 0 -0 0</pose>
          <mass>0.05</mass>
          <inertia>
            <ixx>0.0001</ixx>
            <ixy>1.49367e-09</ixy>
            <ixz>3.12525e-10</ixz>
            <iyy>0.0001</iyy>
            <iyz>2.63475e-06</iyz>
            <izz>0.0001</izz>
          </inertia>
        </inertial>
        <collision name='r_hand_thumb_proximal_link_collision'>
          <pose>0.04 0.171352 -0.382282 0 -0 0</pose>
          <geometry>
            <mesh>
              <scale>0.001 0.001 0.001</scale>
              <uri>model://cer/meshes/dae/sim_cer_r_hand_thumb_proximal.dae</uri>
            </mesh>
          </geometry>
          <max_contacts>10</max_contacts>
          <surface>
            <contact>
              <ode/>
            </contact>
            <bounce/>
            <friction>
              <torsional>
                <ode/>
              </torsional>
              <ode/>
            </friction>
          </surface>
        </collision>
        <visual name='r_hand_thumb_proximal_link_visual'>
          <pose>0.04 0.171352 -0.382282 0 -0 0</pose>
          <geometry>
            <mesh>
              <scale>0.001 0.001 0.001</scale>
              <uri>model://cer/meshes/dae/sim_cer_r_hand_thumb_proximal.dae</uri>
            </mesh>
          </geometry>
        </visual>
        <self_collide>0</self_collide>
        <enable_wind>0</enable_wind>
        <kinematic>0</kinematic>
      </link>
      <joint name='r_hand_thumb_proximal_joint' type='revolute'>
        <child>r_hand_thumb_proximal_link</child>
        <parent>r_hand_root_link</parent>
        <axis>
          <xyz expressed_in='__model__'>-1 -0 0</xyz>
          <limit>
            <lower>0</lower>
            <upper>1.0472</upper>
            <effort>5</effort>
            <velocity>3.14</velocity>
          </limit>
          <dynamics>
            <damping>10</damping>
            <friction>0</friction>
            <spring_reference>0</spring_reference>
            <spring_stiffness>0</spring_stiffness>
          </dynamics>
        </axis>
        <physics>
          <ode>
            <implicit_spring_damper>1</implicit_spring_damper>
            <cfm_damping>1</cfm_damping>
            <limit>
              <cfm>0</cfm>
              <erp>0.2</erp>
            </limit>
          </ode>
        </physics>
      </joint>
      <link name='r_hand_thumb_distal_link'>
        <pose>-0.04 -0.130827 0.211296 0 -0 0</pose>
        <inertial>
          <pose>0.002448 0.014529 -0.005865 0 -0 0</pose>
          <mass>0.05</mass>
          <inertia>
            <ixx>3.85163e-06</ixx>
            <ixy>-1.50194e-10</ixy>
            <ixz>4.04682e-10</ixz>
            <iyy>7.40388e-06</iyy>
            <iyz>9.14021e-07</iyz>
            <izz>8.52416e-06</izz>
          </inertia>
        </inertial>
        <collision name='r_hand_thumb_distal_link_collision'>
          <pose>0.04 0.130827 -0.371296 0 -0 0</pose>
          <geometry>
            <mesh>
              <scale>0.001 0.001 0.001</scale>
              <uri>model://cer/meshes/dae/sim_cer_r_hand_thumb_distal.dae</uri>
            </mesh>
          </geometry>
          <max_contacts>10</max_contacts>
          <surface>
            <contact>
              <ode/>
            </contact>
            <bounce/>
            <friction>
              <torsional>
                <ode/>
              </torsional>
              <ode/>
            </friction>
          </surface>
        </collision>
        <visual name='r_hand_thumb_distal_link_visual'>
          <pose>0.04 0.130827 -0.371296 0 -0 0</pose>
          <geometry>
            <mesh>
              <scale>0.001 0.001 0.001</scale>
              <uri>model://cer/meshes/dae/sim_cer_r_hand_thumb_distal.dae</uri>
            </mesh>
          </geometry>
        </visual>
        <self_collide>0</self_collide>
        <enable_wind>0</enable_wind>
        <kinematic>0</kinematic>
      </link>
      <joint name='r_hand_thumb_distal_joint' type='revolute'>
        <child>r_hand_thumb_distal_link</child>
        <parent>r_hand_thumb_proximal_link</parent>
        <axis>
          <xyz expressed_in='__model__'>-1 -0 0</xyz>
          <limit>
            <lower>0</lower>
            <upper>1.22173</upper>
            <effort>5</effort>
            <velocity>3.14</velocity>
          </limit>
          <dynamics>
            <damping>10</damping>
            <friction>0</friction>
            <spring_reference>0</spring_reference>
            <spring_stiffness>0</spring_stiffness>
          </dynamics>
        </axis>
        <physics>
          <ode>
            <implicit_spring_damper>1</implicit_spring_damper>
            <cfm_damping>1</cfm_damping>
            <limit>
              <cfm>0</cfm>
              <erp>0.2</erp>
            </limit>
          </ode>
        </physics>
      </joint>
      <plugin name='controlboard_torso' filename='libgazebo_yarp_controlboard.so'>
        <yarpConfigurationFile>model://cer/conf/gazebo_cer_torso.ini</yarpConfigurationFile>
      </plugin>
      <plugin name='controlboard_torso_tripod' filename='libgazeboTripod.so'>
        <yarpConfigurationFile>model://cer/conf/gazebo_cer_torso_tripod.ini</yarpConfigurationFile>
      </plugin>
      <plugin name='controlboard_left_upper_arm' filename='libgazebo_yarp_controlboard.so'>
        <yarpConfigurationFile>model://cer/conf/gazebo_cer_left_upper_arm.ini</yarpConfigurationFile>
      </plugin>
      <plugin name='controlboard_left_wrist' filename='libgazebo_yarp_controlboard.so'>
        <yarpConfigurationFile>model://cer/conf/gazebo_cer_left_wrist.ini</yarpConfigurationFile>
      </plugin>
      <plugin name='controlboard_left_wrist_tripod' filename='libgazeboTripod.so'>
        <yarpConfigurationFile>model://cer/conf/gazebo_cer_left_wrist_tripod.ini</yarpConfigurationFile>
      </plugin>
      <plugin name='controlboard_right_upper_arm' filename='libgazebo_yarp_controlboard.so'>
        <yarpConfigurationFile>model://cer/conf/gazebo_cer_right_upper_arm.ini</yarpConfigurationFile>
      </plugin>
      <plugin name='controlboard_right_wrist' filename='libgazebo_yarp_controlboard.so'>
        <yarpConfigurationFile>model://cer/conf/gazebo_cer_right_wrist.ini</yarpConfigurationFile>
      </plugin>
      <plugin name='controlboard_right_wrist_tripod' filename='libgazeboTripod.so'>
        <yarpConfigurationFile>model://cer/conf/gazebo_cer_right_wrist_tripod.ini</yarpConfigurationFile>
      </plugin>
      <plugin name='controlboard_right_arm' filename='libgazebo_yarp_controlboard.so'>
        <yarpConfigurationFile>model://cer/conf/gazebo_cer_right_arm.ini</yarpConfigurationFile>
      </plugin>
      <plugin name='controlboard_left_arm' filename='libgazebo_yarp_controlboard.so'>
        <yarpConfigurationFile>model://cer/conf/gazebo_cer_left_arm.ini</yarpConfigurationFile>
      </plugin>
      <plugin name='controlboard_head' filename='libgazebo_yarp_controlboard.so'>
        <yarpConfigurationFile>model://cer/conf/gazebo_cer_head.ini</yarpConfigurationFile>
      </plugin>
      <plugin name='controlboard_left_hand' filename='libgazebo_yarp_controlboard.so'>
        <yarpConfigurationFile>model://cer/conf/gazebo_cer_left_hand.ini</yarpConfigurationFile>
      </plugin>
      <plugin name='controlboard_right_hand' filename='libgazebo_yarp_controlboard.so'>
        <yarpConfigurationFile>model://cer/conf/gazebo_cer_right_hand.ini</yarpConfigurationFile>
      </plugin>
      <plugin name='mais_left_hand' filename='libgazebo_yarp_maissensor.so'>
        <yarpConfigurationFile>model://cer/conf/gazebo_cer_left_hand_mais.ini</yarpConfigurationFile>
      </plugin>
      <plugin name='mais_right_hand' filename='libgazebo_yarp_maissensor.so'>
        <yarpConfigurationFile>model://cer/conf/gazebo_cer_right_hand_mais.ini</yarpConfigurationFile>
      </plugin>
      <plugin name='controlboard_mobile_base' filename='libgazebo_yarp_controlboard.so'>
        <yarpConfigurationFile>model://cer/conf/gazebo_cer_mobile_base.ini</yarpConfigurationFile>
      </plugin>
      <plugin name='world_interface' filename='libgazebo_yarp_worldinterface.so'>
        <yarpConfigurationFile>model://cer/conf/worldInterface.ini</yarpConfigurationFile>
      </plugin>
      <plugin name='double_laser' filename='libgazebo_yarp_doublelaser.so'>
        <yarpConfigurationFile>model://cer/conf/gazebo_cer_doublelaser.ini</yarpConfigurationFile>
      </plugin>
      <plugin name='robotinterface' filename='libgazebo_yarp_robotinterface.so'>
        <yarpRobotInterfaceConfigurationFile>model://cer/conf/RobotInterfaceTest.xml</yarpRobotInterfaceConfigurationFile>
      </plugin>
      <static>0</static>
      <pose>0.053021 -0.619145 0.16 0 -0 0</pose>
    </model>
    <model name='bookshelf'>
      <static>1</static>
      <link name='link'>
        <inertial>
          <mass>1</mass>
        </inertial>
        <collision name='back'>
          <pose>0 0.005 0.6 0 -0 0</pose>
          <geometry>
            <box>
              <size>0.9 0.01 1.2</size>
            </box>
          </geometry>
          <max_contacts>10</max_contacts>
          <surface>
            <contact>
              <ode/>
            </contact>
            <bounce/>
            <friction>
              <torsional>
                <ode/>
              </torsional>
              <ode/>
            </friction>
          </surface>
        </collision>
        <visual name='visual1'>
          <pose>0 0.005 0.6 0 -0 0</pose>
          <geometry>
            <box>
              <size>0.9 0.01 1.2</size>
            </box>
          </geometry>
          <material>
            <script>
              <uri>file://media/materials/scripts/gazebo.material</uri>
              <name>Gazebo/Wood</name>
            </script>
          </material>
        </visual>
        <collision name='left_side'>
          <pose>0.45 -0.195 0.6 0 -0 0</pose>
          <geometry>
            <box>
              <size>0.02 0.4 1.2</size>
            </box>
          </geometry>
          <max_contacts>10</max_contacts>
          <surface>
            <contact>
              <ode/>
            </contact>
            <bounce/>
            <friction>
              <torsional>
                <ode/>
              </torsional>
              <ode/>
            </friction>
          </surface>
        </collision>
        <visual name='visual2'>
          <pose>0.45 -0.195 0.6 0 -0 0</pose>
          <geometry>
            <box>
              <size>0.02 0.4 1.2</size>
            </box>
          </geometry>
          <material>
            <script>
              <uri>file://media/materials/scripts/gazebo.material</uri>
              <name>Gazebo/Wood</name>
            </script>
          </material>
        </visual>
        <collision name='right_side'>
          <pose>-0.45 -0.195 0.6 0 -0 0</pose>
          <geometry>
            <box>
              <size>0.02 0.4 1.2</size>
            </box>
          </geometry>
          <max_contacts>10</max_contacts>
          <surface>
            <contact>
              <ode/>
            </contact>
            <bounce/>
            <friction>
              <torsional>
                <ode/>
              </torsional>
              <ode/>
            </friction>
          </surface>
        </collision>
        <visual name='visual3'>
          <pose>-0.45 -0.195 0.6 0 -0 0</pose>
          <geometry>
            <box>
              <size>0.02 0.4 1.2</size>
            </box>
          </geometry>
          <material>
            <script>
              <uri>file://media/materials/scripts/gazebo.material</uri>
              <name>Gazebo/Wood</name>
            </script>
          </material>
        </visual>
        <collision name='bottom'>
          <pose>0 -0.195 0.03 0 -0 0</pose>
          <geometry>
            <box>
              <size>0.88 0.4 0.06</size>
            </box>
          </geometry>
          <max_contacts>10</max_contacts>
          <surface>
            <contact>
              <ode/>
            </contact>
            <bounce/>
            <friction>
              <torsional>
                <ode/>
              </torsional>
              <ode/>
            </friction>
          </surface>
        </collision>
        <visual name='visual4'>
          <pose>0 -0.195 0.03 0 -0 0</pose>
          <geometry>
            <box>
              <size>0.88 0.4 0.06</size>
            </box>
          </geometry>
          <material>
            <script>
              <uri>file://media/materials/scripts/gazebo.material</uri>
              <name>Gazebo/Wood</name>
            </script>
          </material>
        </visual>
        <collision name='top'>
          <pose>0 -0.195 1.19 0 -0 0</pose>
          <geometry>
            <box>
              <size>0.88 0.4 0.02</size>
            </box>
          </geometry>
          <max_contacts>10</max_contacts>
          <surface>
            <contact>
              <ode/>
            </contact>
            <bounce/>
            <friction>
              <torsional>
                <ode/>
              </torsional>
              <ode/>
            </friction>
          </surface>
        </collision>
        <visual name='visual5'>
          <pose>0 -0.195 1.19 0 -0 0</pose>
          <geometry>
            <box>
              <size>0.88 0.4 0.02</size>
            </box>
          </geometry>
          <material>
            <script>
              <uri>file://media/materials/scripts/gazebo.material</uri>
              <name>Gazebo/Wood</name>
            </script>
          </material>
        </visual>
        <collision name='low_shelf'>
          <pose>0 -0.195 0.43 0 -0 0</pose>
          <geometry>
            <box>
              <size>0.88 0.4 0.02</size>
            </box>
          </geometry>
          <max_contacts>10</max_contacts>
          <surface>
            <contact>
              <ode/>
            </contact>
            <bounce/>
            <friction>
              <torsional>
                <ode/>
              </torsional>
              <ode/>
            </friction>
          </surface>
        </collision>
        <visual name='visual6'>
          <pose>0 -0.195 0.43 0 -0 0</pose>
          <geometry>
            <box>
              <size>0.88 0.4 0.02</size>
            </box>
          </geometry>
          <material>
            <script>
              <uri>file://media/materials/scripts/gazebo.material</uri>
              <name>Gazebo/Wood</name>
            </script>
          </material>
        </visual>
        <collision name='high_shelf'>
          <pose>0 -0.195 0.8 0 -0 0</pose>
          <geometry>
            <box>
              <size>0.88 0.4 0.02</size>
            </box>
          </geometry>
          <max_contacts>10</max_contacts>
          <surface>
            <contact>
              <ode/>
            </contact>
            <bounce/>
            <friction>
              <torsional>
                <ode/>
              </torsional>
              <ode/>
            </friction>
          </surface>
        </collision>
        <visual name='visual7'>
          <pose>0 -0.195 0.8 0 -0 0</pose>
          <geometry>
            <box>
              <size>0.88 0.4 0.02</size>
            </box>
          </geometry>
          <material>
            <script>
              <uri>file://media/materials/scripts/gazebo.material</uri>
              <name>Gazebo/Wood</name>
            </script>
          </material>
        </visual>
        <self_collide>0</self_collide>
        <enable_wind>0</enable_wind>
        <kinematic>0</kinematic>
      </link>
      <pose>2.7944 -0.503301 0 0 -0 0</pose>
    </model>
    <state world_name='default'>
      <sim_time>28 737000000</sim_time>
      <real_time>65 77195187</real_time>
      <wall_time>1624466570 286648952</wall_time>
      <iterations>28737</iterations>
      <model name='SIM_CER_ROBOT'>
        <pose>0.074666 -0.621511 0.159997 -5e-06 0.008411 -0.02332</pose>
        <scale>1 1 1</scale>
        <link name='chest_link'>
          <pose>0.122603 -0.622627 0.629605 -8.7e-05 0.007591 -0.02332</pose>
          <velocity>0.001017 0.004564 0.000309 0.011245 0.00063 -0.00099</velocity>
          <acceleration>-0.400305 4.68284 0.66378 -2.74353 1.27645 1.57396</acceleration>
          <wrench>-5.20396 60.877 8.62913 0 -0 0</wrench>
        </link>
        <link name='head_link'>
          <pose>0.044661 -0.620761 1.18858 -8.6e-05 0.008328 -0.023318</pose>
          <velocity>0.001407 -0.001604 0.000398 0.011639 0.000726 0.002307</velocity>
          <acceleration>0.092614 -2.66595 0.723944 1.34933 0.785588 -1.42687</acceleration>
          <wrench>0.185228 -5.3319 1.44789 0 -0 0</wrench>
        </link>
        <link name='l_clavicle_link'>
          <pose>0.045564 -0.443749 1.00021 -9.2e-05 0.007643 -0.023319</pose>
          <velocity>0.001458 0.00044 0.002151 0.00747 -0.00157 -0.00226</velocity>
          <acceleration>-0.397722 1.17563 4.29173 -0.763488 -0.003222 2.02984</acceleration>
          <wrench>-0.079544 0.235125 0.858346 0 -0 0</wrench>
        </link>
        <link name='l_elbow_sphere_link'>
          <pose>0.044973 -0.388073 0.753114 0.087113 -0.078883 -0.03089</pose>
          <velocity>0.001799 -0.000783 0.001707 0.005389 0.001706 -0.000387</velocity>
          <acceleration>0.093662 -1.2864 3.39721 1.3366 -0.481615 -0.891238</acceleration>
          <wrench>0.018732 -0.257281 0.679441 0 -0 0</wrench>
        </link>
        <link name='l_forearm_link'>
          <pose>0.050741 -0.382067 0.682605 0.087124 -0.0789 -0.030892</pose>
          <velocity>0.001902 -0.001004 0.001719 0.003725 0.00141 -0.003019</velocity>
          <acceleration>0.079506 -1.195 3.44925 -2.51193 -0.799783 -2.81886</acceleration>
          <wrench>0.047704 -0.717002 2.06955 0 -0 0</wrench>
        </link>
        <link name='l_hand_paddle_distal_link'>
          <pose>0.081111 -0.347057 0.312277 0.087064 -0.078867 -0.030889</pose>
          <velocity>0.001814 2e-05 0.000119 0.001018 0.000318 -0.003753</velocity>
          <acceleration>-0.075671 0.445923 0.239146 1.88418 0.753035 2.9438</acceleration>
          <wrench>-0.003784 0.022296 0.011957 0 -0 0</wrench>
        </link>
        <link name='l_hand_paddle_proximal_link'>
          <pose>0.077577 -0.366593 0.34934 0.08707 -0.078867 -0.030889</pose>
          <velocity>0.001753 -8e-06 9.9e-05 0.001034 0.000281 -0.003781</velocity>
          <acceleration>-0.092189 0.386972 0.212999 1.93461 0.41696 3.00917</acceleration>
          <wrench>-0.004609 0.019349 0.01065 0 -0 0</wrench>
        </link>
        <link name='l_hand_root_link'>
          <pose>0.068756 -0.363303 0.462187 0.087146 -0.078867 -0.030889</pose>
          <velocity>0.0018 -0.000128 0.000109 0.001342 0.000315 -0.00374</velocity>
          <acceleration>-0.100293 0.235864 0.186468 1.7995 -0.380768 0.611599</acceleration>
          <wrench>-0.030088 0.070759 0.05594 0 -0 0</wrench>
        </link>
        <link name='l_hand_thumb_distal_link'>
          <pose>0.074129 -0.435824 0.369138 0.087319 -0.078868 -0.030889</pose>
          <velocity>0.001502 -1.6e-05 2e-06 0.00141 0.000483 -0.003618</velocity>
          <acceleration>-0.383185 0.336836 -0.034935 2.69128 1.0257 -3.07823</acceleration>
          <wrench>-0.019159 0.016842 -0.001747 0 -0 0</wrench>
        </link>
        <link name='l_hand_thumb_proximal_link'>
          <pose>0.073952 -0.396386 0.38355 0.087292 -0.078868 -0.03089</pose>
          <velocity>0.001651 -3.6e-05 6e-05 0.001425 0.000475 -0.00364</velocity>
          <acceleration>-0.256223 0.29044 0.065337 2.7196 0.358644 -2.8841</acceleration>
          <wrench>-0.012811 0.014522 0.003267 0 -0 0</wrench>
        </link>
        <link name='l_shoulder_link'>
          <pose>0.045564 -0.443748 1.00021 0.086863 0.007648 -0.023313</pose>
          <velocity>0.001501 0.000416 0.002 -0.004505 -0.00075 -0.001607</velocity>
          <acceleration>-0.233044 0.589125 3.55753 0.556202 1.15866 -0.667921</acceleration>
          <wrench>-0.116522 0.294563 1.77876 0 -0 0</wrench>
        </link>
        <link name='l_upperarm_FT_sensor_link'>
          <pose>0.045761 -0.400327 0.893579 0.086861 0.007655 -0.023337</pose>
          <velocity>0.00167 -0.000172 0.001816 -0.003763 -0.000605 -0.000872</velocity>
          <acceleration>-0.076968 -0.379771 3.58857 0.702921 -0.430865 -0.176047</acceleration>
          <wrench>-0.061574 -0.303817 2.87086 0 -0 0</wrench>
        </link>
        <link name='l_wrist_cup_eq_link'>
          <pose>0.036871 -0.362317 0.459665 0.087139 -0.078892 -0.030891</pose>
          <velocity>0.001784 2.3e-05 0.000139 0.001244 0.000926 -0.003619</velocity>
          <acceleration>-0.089634 0.194625 0.209853 -1.01805 1.41955 -1.48794</acceleration>
          <wrench>-0.017927 0.038925 0.041971 0 -0 0</wrench>
        </link>
        <link name='l_wrist_slider_eq_link'>
          <pose>0.045137 -0.387903 0.751182 0.087119 -0.078897 -0.030893</pose>
          <velocity>0.002112 -0.001107 3.5e-05 0.003766 0.001393 -0.003143</velocity>
          <acceleration>0.122878 -0.313575 0.155711 -2.14084 0.405961 0.019072</acceleration>
          <wrench>0.036863 -0.094072 0.046713 0 -0 0</wrench>
        </link>
        <link name='mobile_base_body_link'>
          <pose>0.074666 -0.621511 0.159997 -5e-06 0.008411 -0.02332</pose>
          <velocity>0.001592 -0.001915 0.000177 -0.015953 -0.000483 -0.009565</velocity>
          <acceleration>0.417545 -1.50043 0.354407 -0.693951 -0.898501 2.59397</acceleration>
          <wrench>5.84563 -21.0061 4.96169 0 -0 0</wrench>
        </link>
        <link name='mobile_base_l_tyre_link'>
          <pose>0.077907 -0.482552 0.16 -8.5e-05 0.008414 -0.02332</pose>
          <velocity>0.002941 -0.001124 -0.002862 0.003976 0.002716 -0.009617</velocity>
          <acceleration>3.3022 -1.86039 -5.46905 -1.53652 0.417616 -0.410575</acceleration>
          <wrench>9.90659 -5.58118 -16.4072 0 -0 0</wrench>
        </link>
        <link name='mobile_base_r_tyre_link'>
          <pose>0.071425 -0.760468 0.160003 0.000103 0.008414 -0.023319</pose>
          <velocity>0.000317 -0.001041 0.003617 0.005828 0.00021 -0.009577</velocity>
          <acceleration>-2.18793 -1.68821 6.83267 2.18327 0.515769 -0.330242</acceleration>
          <wrench>-6.56381 -5.06464 20.498 0 -0 0</wrench>
        </link>
        <link name='neck_link'>
          <pose>0.031667 -0.620471 1.03031 -8.7e-05 0.00833 -0.023319</pose>
          <velocity>0.00129 0.000159 0.000413 0.01094 0.000689 -0.001249</velocity>
          <acceleration>-0.038586 -1.13407 0.813701 2.19593 1.33181 1.3264</acceleration>
          <wrench>-0.05402 -1.5877 1.13918 0 -0 0</wrench>
        </link>
        <link name='r_clavicle_link'>
          <pose>0.037309 -0.797653 1.00025 -0.000103 0.007629 -0.023332</pose>
          <velocity>0.001078 0.000481 -0.001665 0.012951 -0.0015 -0.000449</velocity>
          <acceleration>0.025107 1.22886 -3.34424 -2.3495 -0.197947 -0.719748</acceleration>
          <wrench>0.005021 0.245772 -0.668848 0 -0 0</wrench>
        </link>
        <link name='r_elbow_sphere_link'>
          <pose>0.034125 -0.853291 0.753156 -0.087341 -0.079031 -0.015725</pose>
          <velocity>0.000915 -0.000571 -0.000911 -0.00515 0.000853 -0.000303</velocity>
          <acceleration>-0.128505 -0.909578 -1.83478 -0.977967 1.2796 -0.056706</acceleration>
          <wrench>-0.025701 -0.181916 -0.366955 0 -0 0</wrench>
        </link>
        <link name='r_forearm_link'>
          <pose>0.03961 -0.859573 0.682646 -0.0873 -0.079007 -0.015726</pose>
          <velocity>0.000852 -0.000629 -0.000788 0.002425 -0.001118 -0.002247</velocity>
          <acceleration>-0.1008 -0.666291 -1.60996 -2.36709 -0.078654 -0.36907</acceleration>
          <wrench>-0.06048 -0.399774 -0.965973 0 -0 0</wrench>
        </link>
        <link name='r_hand_paddle_distal_link'>
          <pose>0.068358 -0.896029 0.312327 -0.087251 -0.078998 -0.015727</pose>
          <velocity>0.000949 -8.8e-05 -4.3e-05 6.8e-05 -0.00011 -0.002188</velocity>
          <acceleration>-0.051087 0.172747 -0.08931 0.390867 -0.213685 2.50593</acceleration>
          <wrench>-0.002554 0.008637 -0.004465 0 -0 0</wrench>
        </link>
        <link name='r_hand_paddle_proximal_link'>
          <pose>0.065734 -0.876342 0.349387 -0.08726 -0.078999 -0.015727</pose>
          <velocity>0.000987 -8.8e-05 -4e-05 5e-06 -7.5e-05 -0.002196</velocity>
          <acceleration>-0.006681 0.166493 -0.080891 0.240114 -0.439194 2.54284</acceleration>
          <wrench>-0.000334 0.008325 -0.004045 0 -0 0</wrench>
        </link>
        <link name='r_hand_root_link'>
          <pose>0.056755 -0.879195 0.462233 -0.087349 -0.078995 -0.015729</pose>
          <velocity>0.000959 -0.000113 -5.6e-05 0.00066 -0.000319 -0.002207</velocity>
          <acceleration>0.058209 0.162069 -0.094062 -0.968222 -1.4452 1.09862</acceleration>
          <wrench>0.017463 0.048621 -0.028219 0 -0 0</wrench>
        </link>
        <link name='r_hand_thumb_distal_link'>
          <pose>0.06526 -0.807018 0.369152 -0.087488 -0.078996 -0.015729</pose>
          <velocity>0.001131 -8.1e-05 -2.9e-05 0.000641 -0.00025 -0.002122</velocity>
          <acceleration>0.342826 0.17254 -0.017106 1.88055 -1.48077 1.4898</acceleration>
          <wrench>0.017141 0.008627 -0.000855 0 -0 0</wrench>
        </link>
        <link name='r_hand_thumb_proximal_link'>
          <pose>0.063497 -0.846405 0.383591 -0.087468 -0.078996 -0.015729</pose>
          <velocity>0.001052 -7.8e-05 -3.5e-05 0.000561 -0.000278 -0.002144</velocity>
          <acceleration>0.221172 0.170851 -0.035258 1.34395 -1.11341 2.7025</acceleration>
          <wrench>0.011059 0.008543 -0.001763 0 -0 0</wrench>
        </link>
        <link name='r_shoulder_link'>
          <pose>0.03731 -0.797655 1.00024 -0.087044 0.007632 -0.023324</pose>
          <velocity>0.001017 0.000536 -0.001318 -0.005468 0.000107 -0.000646</velocity>
          <acceleration>-0.01634 0.679199 -2.12878 1.66055 -1.03087 -0.333828</acceleration>
          <wrench>-0.00817 0.3396 -1.06439 0 -0 0</wrench>
        </link>
        <link name='r_upperarm_FT_sensor_link'>
          <pose>0.035483 -0.841059 0.893618 -0.087058 0.007636 -0.023304</pose>
          <velocity>0.000967 -1.3e-05 -0.000985 -0.004197 0.000317 -0.000262</velocity>
          <acceleration>-0.076427 -0.140255 -1.95268 -0.336064 1.20181 -0.67439</acceleration>
          <wrench>-0.061142 -0.112204 -1.56215 0 -0 0</wrench>
        </link>
        <link name='r_wrist_cup_eq_link'>
          <pose>0.024858 -0.878694 0.459707 -0.07931 0.087086 1.54816</pose>
          <velocity>0.00099 1.6e-05 -8.9e-05 0.001989 -0.001154 -0.002181</velocity>
          <acceleration>0.081426 0.262226 -0.108076 -2.97989 -1.36542 0.769201</acceleration>
          <wrench>0.016285 0.052445 -0.021615 0 -0 0</wrench>
        </link>
        <link name='r_wrist_slider_eq_link'>
          <pose>0.034276 -0.853468 0.75122 -0.087297 -0.079008 -0.015726</pose>
          <velocity>0.000721 -0.000735 -4e-06 0.002587 -0.001165 -0.002207</velocity>
          <acceleration>-0.054044 -0.096679 -0.063478 -2.46889 0.997203 2.76906</acceleration>
          <wrench>-0.016213 -0.029004 -0.019043 0 -0 0</wrench>
        </link>
        <link name='torso_pin_eq_link'>
          <pose>0.122603 -0.622627 0.629611 3.14148 0.008443 -0.02332</pose>
          <velocity>0.001162 0.00481 0.000226 -0.019956 -0.001184 -0.009768</velocity>
          <acceleration>-0.380737 10.1795 0.446512 -0.969151 -1.03087 -2.34367</acceleration>
          <wrench>-0.571105 15.2692 0.669768 0 -0 0</wrench>
        </link>
        <link name='torso_platform_link'>
          <pose>0.122603 -0.622627 0.629608 -9.2e-05 0.007707 -0.02332</pose>
          <velocity>0.00109 0.004701 0.000261 0.004572 0.000492 -0.009571</velocity>
          <acceleration>-0.524697 9.96064 0.514794 2.63813 0.901431 -3.09574</acceleration>
          <wrench>-0.787045 14.941 0.772191 0 -0 0</wrench>
        </link>
        <link name='torso_slider_eq_link'>
          <pose>0.119249 -0.62255 0.230624 -4e-06 0.008411 -0.02332</pose>
          <velocity>0.001565 -0.001259 0.00023 -0.015424 -0.000892 -0.009716</velocity>
          <acceleration>-0.017391 5.28085 0.49733 -2.61234 -1.31113 -0.716851</acceleration>
          <wrench>-0.130431 39.6063 3.72998 0 -0 0</wrench>
        </link>
      </model>
      <model name='bookshelf'>
        <pose>2.7944 -0.503301 0 0 0 -1.49464</pose>
        <scale>1 1 1</scale>
        <link name='link'>
          <pose>2.7944 -0.503301 0 0 0 -1.49464</pose>
          <velocity>0 0 0 0 -0 0</velocity>
          <acceleration>0 0 0 0 -0 0</acceleration>
          <wrench>0 0 0 0 -0 0</wrench>
        </link>
      </model>
      <model name='ground_plane'>
        <pose>0 0 0 0 -0 0</pose>
        <scale>1 1 1</scale>
        <link name='link'>
          <pose>0 0 0 0 -0 0</pose>
          <velocity>0 0 0 0 -0 0</velocity>
          <acceleration>0 0 0 0 -0 0</acceleration>
          <wrench>0 0 0 0 -0 0</wrench>
        </link>
      </model>
      <light name='sun'>
        <pose>0 0 10 0 -0 0</pose>
      </light>
    </state>
    <gui fullscreen='0'>
      <camera name='user_camera'>
        <pose>5 -5 2 0 0.275643 2.35619</pose>
        <view_controller>orbit</view_controller>
        <projection_type>perspective</projection_type>
      </camera>
    </gui>
  </world>
</sdf>
